Workbook

Sheet Y1(Task3)
A1: Part | B1: Avg_Annual_Demand_Units | C1: Weekly_Demand_StdDev_Units | D1: Weekly_Robust_Demand_99p5_Units | E1: Total_Minutes_Per_Unit | F1: Weekly_Robust_Net_Minutes | G1: Weekly_Robust_Gross_Minutes | K1: Time | L1: A | M1: B | N1: C | O1: D | P1: E | Q1: F | R1: G | S1: H | T1: I | U1: J | V1: K | W1: L | X1: M | Z1: Distance | AA1: A | AB1: B | AC1: C | AD1: D | AE1: E | AF1: F | AG1: G | AH1: H | AI1: I | AJ1: J | AK1: K | AL1: L | AM1: M
A2: P1 | B2: 1090000 | C2: 1503.3296 | D2: 30602.933 | E2: 12.75 | F2: 316631.7 | G2: 442389.33 | K2: P1 | L2: 1 | M2: 5 | N2: 0.5 | O2: 2.5 | P2: 0 | Q2: 0 | R2: 0 | S2: 0 | T2: 1.25 | U2: 2.5 | V2: 0 | W2: 0 | X2: 0 | Z2: A | AA2: 0 | AB2: 146 | AC2: 280 | AD2: 0 | AE2: 0 | AF2: 0 | AG2: 0 | AH2: 0 | AI2: 0 | AJ2: 0 | AK2: 0 | AL2: 0 | AM2: 0
A3: P2 | B3: 580000 | C3: 824.62113 | D3: 15927.5 | E3: 7.75 | F3: 102903.95 | G3: 139952.52 | K3: P2 | L3: 1.25 | M3: 0 | N3: 0.5 | O3: 2.5 | P3: 0 | Q3: 0 | R3: 0 | S3: 1 | T3: 0 | U3: 2.5 | V3: 0 | W3: 0 | X3: 0 | Z3: B | AA3: 146 | AB3: 0 | AC3: 134 | AD3: 307 | AE3: 0 | AF3: 0 | AG3: 0 | AH3: 0 | AI3: 0 | AJ3: 0 | AK3: 0 | AL3: 0 | AM3: 0
A4: P3 | B4: 320000 | C4: 806.22577 | D4: 8293.0769 | E4: 9.5 | F4: 78190.188 | G4: 89324.525 | K4: P3 | L4: 0 | M4: 1.75 | N4: 0.75 | O4: 3 | P4: 0 | Q4: 0 | R4: 0 | S4: 0 | T4: 1.5 | U4: 2.5 | V4: 0 | W4: 0 | X4: 0 | Z4: C | AA4: 0 | AB4: 0 | AC4: 0 | AD4: 172 | AE4: 0 | AF4: 0 | AG4: 0 | AH4: 0 | AI4: =227+268 -> 495 | AJ4: 0 | AK4: 0 | AL4: 0 | AM4: 0
A5: P4 | B5: 480000 | C5: 748.33148 | D5: 13509.231 | E5: 7.5 | F5: 83687.575 | G5: 114874.41 | K5: P4 | L5: 1 | M5: 2 | N5: 0 | O5: 3 | P5: 0 | Q5: 0 | R5: 0.25 | S5: 1.25 | T5: 0 | U5: 0 | V5: 0 | W5: 0 | X5: 0 | Z5: D | AA5: 0 | AB5: 0 | AC5: 172 | AD5: 0 | AE5: 0 | AF5: 0 | AG5: =163+114 -> 277 | AH5: 114 | AI5: =401+268 -> 669 | AJ5: 0 | AK5: 0 | AL5: 0 | AM5: 0
A6: P5 | B6: 360000 | C6: 632.45553 | D6: 10488.462 | E6: 7.5 | F6: 64141.308 | G6: 89187.598 | K6: P5 | L6: 0 | M6: 1.5 | N6: 0.75 | O6: 3.5 | P6: 0 | Q6: 0 | R6: 0 | S6: 0 | T6: 1.75 | U6: 0 | V6: 0 | W6: 0 | X6: 0 | Z6: E | AA6: 0 | AB6: 0 | AC6: 0 | AD6: 0 | AE6: 0 | AF6: 152 | AG6: 267 | AH6: 445 | AI6: 0 | AJ6: 0 | AK6: 0 | AL6: 0 | AM6: 0
A7: P6 | B7: 210000 | C7: 223.6068 | D7: 5836.0096 | E7: 10.5 | F7: 48451.562 | G7: 69476.305 | K7: P6 | L7: 0.75 | M7: 1.25 | N7: 0.5 | O7: 3 | P7: 0 | Q7: 0 | R7: 0 | S7: 1 | T7: 1.25 | U7: 2.75 | V7: 0 | W7: 0 | X7: 0 | Z7: F | AA7: 0 | AB7: 0 | AC7: =105+113 -> 218 | AD7: 0 | AE7: 0 | AF7: 0 | AG7: 114 | AH7: 293 | AI7: =112+156 -> 268 | AJ7: 0 | AK7: 0 | AL7: 0 | AM7: 0
A8: P7 | B8: 720000 | C8: 894.42719 | D8: 20660 | E8: 10 | F8: 161500.46 | G8: 234240.36 | K8: P7 | L8: 0 | M8: 0 | N8: 0.75 | O8: 3.5 | P8: 1 | Q8: 1.5 | R8: 0 | S8: 0 | T8: 1.25 | U8: 2 | V8: 0 | W8: 0 | X8: 0 | Z8: G | AA8: 0 | AB8: 0 | AC8: 0 | AD8: 0 | AE8: 266 | AF8: 114 | AG8: 0 | AH8: 178 | AI8: =236+150 -> 386 | AJ8: 0 | AK8: 0 | AL8: 0 | AM8: 0
A9: P8 | B9: 240000 | C9: 800 | D9: 6041.5385 | E9: 4.75 | F9: 31711.228 | G9: 32536.63 | K9: P8 | L9: 0 | M9: 0 | N9: 0 | O9: 0 | P9: 1.25 | Q9: 0 | R9: 0 | S9: 2 | T9: 1 | U9: 0.5 | V9: 0 | W9: 0 | X9: 0 | Z9: H | AA9: 0 | AB9: 0 | AC9: 0 | AD9: 0 | AE9: 0 | AF9: 0 | AG9: 0 | AH9: 0 | AI9: =147+417 -> 564 | AJ9: =150+158 -> 308 | AK9: 0 | AL9: 0 | AM9: 0
A10: P9 | B10: 460000 | C10: 721.11026 | D10: 13401.923 | E10: 8.5 | F10: 90980.692 | G10: 129156.85 | K10: P9 | L10: 0 | M10: 0 | N10: 0 | O10: 0 | P10: 1.25 | Q10: 1.75 | R10: 1.25 | S10: 0 | T10: 1.25 | U10: 3 | V10: 0 | W10: 0 | X10: 0 | Z10: I | AA10: 0 | AB10: 0 | AC10: 0 | AD10: 0 | AE10: 0 | AF10: 0 | AG10: 0 | AH10: 0 | AI10: 0 | AJ10: 265 | AK10: 0 | AL10: 0 | AM10: 0
A11: P10 | B11: 240000 | C11: 374.16574 | D11: 6630.8173 | E11: 6.5 | F11: 36264.616 | G11: 48866.567 | K11: P10 | L11: 0 | M11: 0 | N11: 0 | O11: 0 | P11: 1.5 | Q11: 1.75 | R11: 0 | S11: 0 | T11: 1.25 | U11: 2 | V11: 0 | W11: 0 | X11: 0 | Z11: J | AA11: 0 | AB11: 0 | AC11: 0 | AD11: 0 | AE11: 0 | AF11: 0 | AG11: 0 | AH11: 0 | AI11: 265 | AJ11: 0 | AK11: 0 | AL11: 0 | AM11: 0
A12: P11 | B12: 420000 | C12: 447.2136 | D12: 11672.019 | E12: 4 | F12: 36915.476 | G12: 52934.328 | K12: P11 | L12: 0 | M12: 0 | N12: 0 | O12: 0 | P12: 2.5 | Q12: 0 | R12: 0.75 | S12: 0 | T12: 0.75 | U12: 0 | V12: 0 | W12: 0 | X12: 0 | Z12: K | AA12: 0 | AB12: 0 | AC12: 0 | AD12: 0 | AE12: 0 | AF12: 0 | AG12: 0 | AH12: 0 | AI12: 0 | AJ12: 0 | AK12: 0 | AL12: 83 | AM12: 86
A13: P12 | B13: 520000 | C13: 565.68542 | D13: 14337.885 | E13: 6 | F13: 68742.655 | G13: 97536.63 | K13: P12 | L13: 0 | M13: 0 | N13: 0 | O13: 0 | P13: 1 | Q13: 1 | R13: 0.5 | S13: 0 | T13: 1.25 | U13: 2.25 | V13: 0 | W13: 0 | X13: 0 | Z13: L | AA13: 0 | AB13: 0 | AC13: 0 | AD13: 0 | AE13: 0 | AF13: 0 | AG13: 0 | AH13: 0 | AI13: 0 | AJ13: 0 | AK13: 83 | AL13: 0 | AM13: 86
A14: P13 | B14: 260000 | C14: 282.84271 | D14: 7168.9423 | E14: 7.5 | F14: 42964.159 | G14: 60960.394 | K14: P13 | L14: 0 | M14: 0 | N14: 0 | O14: 0 | P14: 1.25 | Q14: 2.25 | R14: 0.75 | S14: 2 | T14: 1.25 | U14: 0 | V14: 0 | W14: 0 | X14: 0 | Z14: M | AA14: 0 | AB14: 0 | AC14: 0 | AD14: 0 | AE14: 0 | AF14: 0 | AG14: 0 | AH14: 0 | AI14: 0 | AJ14: 0 | AK14: 0 | AL14: 86 | AM14: 0
A15: P14 | B15: 940000 | C15: 1095.4451 | D15: 26752.692 | E15: 4.75 | F15: 99268.363 | G15: 144076.29 | K15: P14 | L15: 0 | M15: 0 | N15: 0 | O15: 0 | P15: 1 | Q15: 1.5 | R15: 0.5 | S15: 1.75 | T15: 0 | U15: 0 | V15: 0 | W15: 0 | X15: 0
A16: P15 | B16: 120000 | C16: 400 | D16: 3020.7692 | E16: 7.5 | F16: 25035.18 | G16: 25686.813 | K16: P15 | L16: 0 | M16: 0 | N16: 0 | O16: 0 | P16: 0.75 | Q16: 1.25 | R16: 0.5 | S16: 2.5 | T16: 0 | U16: 2.5 | V16: 0 | W16: 0 | X16: 0
A17: P16 | B17: 620000 | C17: 1216.5525 | D17: 18063.462 | E17: 10 | F17: 150567.09 | G17: 204801.15 | K17: P16 | L17: 0 | M17: 0 | N17: 0 | O17: 0 | P17: 0 | Q17: 1.25 | R17: 0 | S17: 5 | T17: 1.25 | U17: 2.5 | V17: 0 | W17: 0 | X17: 0 | Z17: Capacity | AA17: A | AB17: B | AC17: C | AD17: D | AE17: E | AF17: F | AG17: G | AH17: H | AI17: I | AJ17: J | AK17: K | AL17: L | AM17: M
A18: P17 | B18: 260000 | C18: 282.84271 | D18: 7168.9423 | E18: 7.25 | F18: 41532.02 | G18: 58928.381 | K18: P17 | L18: 0 | M18: 0 | N18: 0 | O18: 0 | P18: 0 | Q18: 0 | R18: 0 | S18: 0 | T18: 0 | U18: 0 | V18: 0.75 | W18: 3 | X18: 3.5 | Z18: P1 | AA18: =L2*$D$2 -> 30602.933 | AB18: =M2*$D$2 -> 153014.66 | AC18: =N2*$D$2 -> 15301.466 | AD18: =O2*$D$2 -> 76507.332 | AE18: =P2*$D$2 -> 0 | AF18: =Q2*$D$2 -> 0 | AG18: =R2*$D$2 -> 0 | AH18: =S2*$D$2 -> 0 | ... AM18: =X2*$D$2 -> 0
A19: P18 | B19: 620000 | C19: 600 | D19: 17251.346 | E19: 6.25 | F19: 84178.591 | G19: 122245.93 | K19: P18 | L19: 0 | M19: 0 | N19: 0 | O19: 0 | P19: 0 | Q19: 0 | R19: 0 | S19: 0 | T19: 0 | U19: 0 | V19: 1.25 | W19: 1.25 | X19: 3.75 | Z19: P2 | AA19: =L3*$D$3 -> 19909.375 | AB19: =M3*$D$3 -> 0 | AC19: =N3*$D$3 -> 7963.75 | AD19: =O3*$D$3 -> 39818.75 | AE19: =P3*$D$3 -> 0 | AF19: =Q3*$D$3 -> 0 | AG19: =R3*$D$3 -> 0 | AH19: =S3*$D$3 -> 15927.5 | ... AM19: =X3*$D$3 -> 0
A20: P19 | B20: 1040000 | C20: 1500 | D20: 29270 | E20: 10.5 | F20: 250569.31 | G20: 348452.38 | K20: P19 | L20: 0 | M20: 0 | N20: 0 | O20: 0 | P20: 0 | Q20: 0 | R20: 0 | S20: 0 | T20: 0 | U20: 0 | V20: 0 | W20: 4.25 | X20: 6.25 | Z20: P3 | AA20: =L4*$D$4 -> 0 | AB20: =M4*$D$4 -> 14512.885 | AC20: =N4*$D$4 -> 6219.8077 | AD20: =O4*$D$4 -> 24879.231 | AE20: =P4*$D$4 -> 0 | AF20: =Q4*$D$4 -> 0 | AG20: =R4*$D$4 -> 0 | AH20: =S4*$D$4 -> 0 | ... AM20: =X4*$D$4 -> 0
A21: P20 | B21: 770000 | C21: 1153.2563 | D21: 21720.577 | E21: 5.75 | F21: 102225.13 | G21: 141602.4 | K21: P20 | L21: 0 | M21: 0 | N21: 0 | O21: 0 | P21: 0 | Q21: 0 | R21: 0 | S21: 0 | T21: 0 | U21: 0 | V21: 0.75 | W21: 2 | X21: 3 | Z21: P4 | AA21: =L5*$D$5 -> 13509.231 | AB21: =M5*$D$5 -> 27018.462 | AC21: =N5*$D$5 -> 0 | AD21: =O5*$D$5 -> 40527.692 | AE21: =P5*$D$5 -> 0 | AF21: =Q5*$D$5 -> 0 | AG21: =R5*$D$5 -> 3377.3077 | AH21: =S5*$D$5 -> 16886.538 | ... AM21: =X5*$D$5 -> 0
Z22: P5 | AA22: =L6*$D$6 -> 0 | AB22: =M6*$D$6 -> 15732.692 | AC22: =N6*$D$6 -> 7866.3462 | AD22: =O6*$D$6 -> 36709.615 | AE22: =P6*$D$6 -> 0 | AF22: =Q6*$D$6 -> 0 | AG22: =R6*$D$6 -> 0 | AH22: =S6*$D$6 -> 0 | ... AM22: =X6*$D$6 -> 0
Z23: P6 | AA23: =L7*$D$7 -> 4377.0072 | AB23: =M7*$D$7 -> 7295.012 | AC23: =N7*$D$7 -> 2918.0048 | AD23: =O7*$D$7 -> 17508.029 | AE23: =P7*$D$7 -> 0 | AF23: =Q7*$D$7 -> 0 | AG23: =R7*$D$7 -> 0 | AH23: =S7*$D$7 -> 5836.0096 | ... AM23: =X7*$D$7 -> 0
K24: Proportion | L24: A | M24: B | N24: C | O24: D | P24: E | Q24: F | R24: G | S24: H | T24: I | U24: J | V24: K | W24: L | X24: M | Z24: P7 | AA24: =L8*$D$8 -> 0 | AB24: =M8*$D$8 -> 0 | AC24: =N8*$D$8 -> 15495 | AD24: =O8*$D$8 -> 72310 | AE24: =P8*$D$8 -> 20660 | AF24: =Q8*$D$8 -> 30990 | AG24: =R8*$D$8 -> 0 | AH24: =S8*$D$8 -> 0 | ... AM24: =X8*$D$8 -> 0
K25: P1 | L25: =L2/$E$2 -> 0.078431373 | M25: =M2/$E$2 -> 0.39215686 | N25: =N2/$E$2 -> 0.039215686 | O25: =O2/$E$2 -> 0.19607843 | P25: =P2/$E$2 -> 0 | Q25: =Q2/$E$2 -> 0 | R25: =R2/$E$2 -> 0 | S25: =S2/$E$2 -> 0 | ... X25: =X2/$E$2 -> 0 | Z25: P8 | AA25: =L9*$D$9 -> 0 | AB25: =M9*$D$9 -> 0 | AC25: =N9*$D$9 -> 0 | AD25: =O9*$D$9 -> 0 | AE25: =P9*$D$9 -> 7551.9231 | AF25: =Q9*$D$9 -> 0 | AG25: =R9*$D$9 -> 0 | AH25: =S9*$D$9 -> 12083.077 | ... AM25: =X9*$D$9 -> 0
K26: P2 | L26: =L3/$E$3 -> 0.16129032 | M26: =M3/$E$3 -> 0 | N26: =N3/$E$3 -> 0.064516129 | O26: =O3/$E$3 -> 0.32258065 | P26: =P3/$E$3 -> 0 | Q26: =Q3/$E$3 -> 0 | R26: =R3/$E$3 -> 0 | S26: =S3/$E$3 -> 0.12903226 | ... X26: =X3/$E$3 -> 0 | Z26: P9 | AA26: =L10*$D$10 -> 0 | AB26: =M10*$D$10 -> 0 | AC26: =N10*$D$10 -> 0 | AD26: =O10*$D$10 -> 0 | AE26: =P10*$D$10 -> 16752.404 | AF26: =Q10*$D$10 -> 23453.365 | AG26: =R10*$D$10 -> 16752.404 | AH26: =S10*$D$10 -> 0 | ... AM26: =X10*$D$10 -> 0
K27: P3 | L27: =L4/$E$4 -> 0 | M27: =M4/$E$4 -> 0.18421053 | N27: =N4/$E$4 -> 0.078947368 | O27: =O4/$E$4 -> 0.31578947 | P27: =P4/$E$4 -> 0 | Q27: =Q4/$E$4 -> 0 | R27: =R4/$E$4 -> 0 | S27: =S4/$E$4 -> 0 | ... X27: =X4/$E$4 -> 0 | Z27: P10 | AA27: =L11*$D$11 -> 0 | AB27: =M11*$D$11 -> 0 | AC27: =N11*$D$11 -> 0 | AD27: =O11*$D$11 -> 0 | AE27: =P11*$D$11 -> 9946.226 | AF27: =Q11*$D$11 -> 11603.93 | AG27: =R11*$D$11 -> 0 | AH27: =S11*$D$11 -> 0 | ... AM27: =X11*$D$11 -> 0
K28: P4 | L28: =L5/$E$5 -> 0.13333333 | M28: =M5/$E$5 -> 0.26666667 | N28: =N5/$E$5 -> 0 | O28: =O5/$E$5 -> 0.4 | P28: =P5/$E$5 -> 0 | Q28: =Q5/$E$5 -> 0 | R28: =R5/$E$5 -> 0.033333333 | S28: =S5/$E$5 -> 0.16666667 | ... X28: =X5/$E$5 -> 0 | Z28: P11 | AA28: =L12*$D$12 -> 0 | AB28: =M12*$D$12 -> 0 | AC28: =N12*$D$12 -> 0 | AD28: =O12*$D$12 -> 0 | AE28: =P12*$D$12 -> 29180.048 | AF28: =Q12*$D$12 -> 0 | AG28: =R12*$D$12 -> 8754.0144 | AH28: =S12*$D$12 -> 0 | ... AM28: =X12*$D$12 -> 0
K29: P5 | L29: =L6/$E$6 -> 0 | M29: =M6/$E$6 -> 0.2 | N29: =N6/$E$6 -> 0.1 | O29: =O6/$E$6 -> 0.46666667 | P29: =P6/$E$6 -> 0 | Q29: =Q6/$E$6 -> 0 | R29: =R6/$E$6 -> 0 | S29: =S6/$E$6 -> 0 | ... X29: =X6/$E$6 -> 0 | Z29: P12 | AA29: =L13*$D$13 -> 0 | AB29: =M13*$D$13 -> 0 | AC29: =N13*$D$13 -> 0 | AD29: =O13*$D$13 -> 0 | AE29: =P13*$D$13 -> 14337.885 | AF29: =Q13*$D$13 -> 14337.885 | AG29: =R13*$D$13 -> 7168.9423 | AH29: =S13*$D$13 -> 0 | ... AM29: =X13*$D$13 -> 0
K30: P6 | L30: =L7/$E$7 -> 0.071428571 | M30: =M7/$E$7 -> 0.11904762 | N30: =N7/$E$7 -> 0.047619048 | O30: =O7/$E$7 -> 0.28571429 | P30: =P7/$E$7 -> 0 | Q30: =Q7/$E$7 -> 0 | R30: =R7/$E$7 -> 0 | S30: =S7/$E$7 -> 0.095238095 | ... X30: =X7/$E$7 -> 0 | Z30: P13 | AA30: =L14*$D$14 -> 0 | AB30: =M14*$D$14 -> 0 | AC30: =N14*$D$14 -> 0 | AD30: =O14*$D$14 -> 0 | AE30: =P14*$D$14 -> 8961.1779 | AF30: =Q14*$D$14 -> 16130.12 | AG30: =R14*$D$14 -> 5376.7067 | AH30: =S14*$D$14 -> 14337.885 | ... AM30: =X14*$D$14 -> 0
K31: P7 | L31: =L8/$E$8 -> 0 | M31: =M8/$E$8 -> 0 | N31: =N8/$E$8 -> 0.075 | O31: =O8/$E$8 -> 0.35 | P31: =P8/$E$8 -> 0.1 | Q31: =Q8/$E$8 -> 0.15 | R31: =R8/$E$8 -> 0 | S31: =S8/$E$8 -> 0 | ... X31: =X8/$E$8 -> 0 | Z31: P14 | AA31: =L15*$D$15 -> 0 | AB31: =M15*$D$15 -> 0 | AC31: =N15*$D$15 -> 0 | AD31: =O15*$D$15 -> 0 | AE31: =P15*$D$15 -> 26752.692 | AF31: =Q15*$D$15 -> 40129.038 | AG31: =R15*$D$15 -> 13376.346 | AH31: =S15*$D$15 -> 46817.212 | ... AM31: =X15*$D$15 -> 0
K32: P8 | L32: =L9/$E$9 -> 0 | M32: =M9/$E$9 -> 0 | N32: =N9/$E$9 -> 0 | O32: =O9/$E$9 -> 0 | P32: =P9/$E$9 -> 0.26315789 | Q32: =Q9/$E$9 -> 0 | R32: =R9/$E$9 -> 0 | S32: =S9/$E$9 -> 0.42105263 | ... X32: =X9/$E$9 -> 0 | Z32: P15 | AA32: =L16*$D$16 -> 0 | AB32: =M16*$D$16 -> 0 | AC32: =N16*$D$16 -> 0 | AD32: =O16*$D$16 -> 0 | AE32: =P16*$D$16 -> 2265.5769 | AF32: =Q16*$D$16 -> 3775.9615 | AG32: =R16*$D$16 -> 1510.3846 | AH32: =S16*$D$16 -> 7551.9231 | ... AM32: =X16*$D$16 -> 0
K33: P9 | L33: =L10/$E$10 -> 0 | M33: =M10/$E$10 -> 0 | N33: =N10/$E$10 -> 0 | O33: =O10/$E$10 -> 0 | P33: =P10/$E$10 -> 0.14705882 | Q33: =Q10/$E$10 -> 0.20588235 | R33: =R10/$E$10 -> 0.14705882 | S33: =S10/$E$10 -> 0 | ... X33: =X10/$E$10 -> 0 | Z33: P16 | AA33: =L17*$D$17 -> 0 | AB33: =M17*$D$17 -> 0 | AC33: =N17*$D$17 -> 0 | AD33: =O17*$D$17 -> 0 | AE33: =P17*$D$17 -> 0 | AF33: =Q17*$D$17 -> 22579.327 | AG33: =R17*$D$17 -> 0 | AH33: =S17*$D$17 -> 90317.308 | ... AM33: =X17*$D$17 -> 0
K34: P10 | L34: =L11/$E$11 -> 0 | M34: =M11/$E$11 -> 0 | N34: =N11/$E$11 -> 0 | O34: =O11/$E$11 -> 0 | P34: =P11/$E$11 -> 0.23076923 | Q34: =Q11/$E$11 -> 0.26923077 | R34: =R11/$E$11 -> 0 | S34: =S11/$E$11 -> 0 | ... X34: =X11/$E$11 -> 0 | Z34: P17 | AA34: =L18*$D$18 -> 0 | AB34: =M18*$D$18 -> 0 | AC34: =N18*$D$18 -> 0 | AD34: =O18*$D$18 -> 0 | AE34: =P18*$D$18 -> 0 | AF34: =Q18*$D$18 -> 0 | AG34: =R18*$D$18 -> 0 | AH34: =S18*$D$18 -> 0 | ... AM34: =X18*$D$18 -> 25091.298
K35: P11 | L35: =L12/$E$12 -> 0 | M35: =M12/$E$12 -> 0 | N35: =N12/$E$12 -> 0 | O35: =O12/$E$12 -> 0 | P35: =P12/$E$12 -> 0.625 | Q35: =Q12/$E$12 -> 0 | R35: =R12/$E$12 -> 0.1875 | S35: =S12/$E$12 -> 0 | ... X35: =X12/$E$12 -> 0 | Z35: P18 | AA35: =L19*$D$19 -> 0 | AB35: =M19*$D$19 -> 0 | AC35: =N19*$D$19 -> 0 | AD35: =O19*$D$19 -> 0 | AE35: =P19*$D$19 -> 0 | AF35: =Q19*$D$19 -> 0 | AG35: =R19*$D$19 -> 0 | AH35: =S19*$D$19 -> 0 | ... AM35: =X19*$D$19 -> 64692.548
K36: P12 | L36: =L13/$E$13 -> 0 | M36: =M13/$E$13 -> 0 | N36: =N13/$E$13 -> 0 | O36: =O13/$E$13 -> 0 | P36: =P13/$E$13 -> 0.16666667 | Q36: =Q13/$E$13 -> 0.16666667 | R36: =R13/$E$13 -> 0.083333333 | S36: =S13/$E$13 -> 0 | ... X36: =X13/$E$13 -> 0 | Z36: P19 | AA36: =L20*$D$20 -> 0 | AB36: =M20*$D$20 -> 0 | AC36: =N20*$D$20 -> 0 | AD36: =O20*$D$20 -> 0 | AE36: =P20*$D$20 -> 0 | AF36: =Q20*$D$20 -> 0 | AG36: =R20*$D$20 -> 0 | AH36: =S20*$D$20 -> 0 | ... AM36: =X20*$D$20 -> 182937.5
K37: P13 | L37: =L14/$E$14 -> 0 | M37: =M14/$E$14 -> 0 | N37: =N14/$E$14 -> 0 | O37: =O14/$E$14 -> 0 | P37: =P14/$E$14 -> 0.16666667 | Q37: =Q14/$E$14 -> 0.3 | R37: =R14/$E$14 -> 0.1 | S37: =S14/$E$14 -> 0.26666667 | ... X37: =X14/$E$14 -> 0 | Z37: P20 | AA37: =L21*$D$21 -> 0 | AB37: =M21*$D$21 -> 0 | AC37: =N21*$D$21 -> 0 | AD37: =O21*$D$21 -> 0 | AE37: =P21*$D$21 -> 0 | AF37: =Q21*$D$21 -> 0 | AG37: =R21*$D$21 -> 0 | AH37: =S21*$D$21 -> 0 | ... AM37: =X21*$D$21 -> 65161.731
K38: P14 | L38: =L15/$E$15 -> 0 | M38: =M15/$E$15 -> 0 | N38: =N15/$E$15 -> 0 | O38: =O15/$E$15 -> 0 | P38: =P15/$E$15 -> 0.21052632 | Q38: =Q15/$E$15 -> 0.31578947 | R38: =R15/$E$15 -> 0.10526316 | S38: =S15/$E$15 -> 0.36842105 | ... X38: =X15/$E$15 -> 0 | Z38: Sum | AA38: =SUM(AA18:AA37) -> 68398.546 | AB38: =SUM(AB18:AB37) -> 217573.71 | AC38: =SUM(AC18:AC37) -> 55764.375 | AD38: =SUM(AD18:AD37) -> 308260.65 | AE38: =SUM(AE18:AE37) -> 136407.93 | AF38: =SUM(AF18:AF37) -> 162999.63 | AG38: =SUM(AG18:AG37) -> 56316.106 | AH38: =SUM(AH18:AH37) -> 209757.45 | ... AM38: =SUM(AM18:AM37) -> 337883.08
K39: P15 | L39: =L16/$E$16 -> 0 | M39: =M16/$E$16 -> 0 | N39: =N16/$E$16 -> 0 | O39: =O16/$E$16 -> 0 | P39: =P16/$E$16 -> 0.1 | Q39: =Q16/$E$16 -> 0.16666667 | R39: =R16/$E$16 -> 0.066666667 | S39: =S16/$E$16 -> 0.33333333 | ... X39: =X16/$E$16 -> 0 | Z39: Sum Capacity | AA39: =5*16*60*L78 -> 81600 | AB39: =5*16*60*M78 -> 249600 | AC39: =5*16*60*N78 -> 67200 | AD39: =5*16*60*O78 -> 350400 | AE39: =5*16*60*P78 -> 158400 | AF39: =5*16*60*Q78 -> 187200 | AG39: =5*16*60*R78 -> 67200 | AH39: =5*16*60*S78 -> 240000 | ... AM39: =5*16*60*X78 -> 384000
K40: P16 | L40: =L17/$E$17 -> 0 | M40: =M17/$E$17 -> 0 | N40: =N17/$E$17 -> 0 | O40: =O17/$E$17 -> 0 | P40: =P17/$E$17 -> 0 | Q40: =Q17/$E$17 -> 0.125 | R40: =R17/$E$17 -> 0 | S40: =S17/$E$17 -> 0.5 | ... X40: =X17/$E$17 -> 0 | Z40: Utilization | AA40: =AA38/AA39 -> 0.83821747 | AB40: =AB38/AB39 -> 0.87168956 | AC40: =AC38/AC39 -> 0.82982701 | AD40: =AD38/AD39 -> 0.8797393 | AE40: =AE38/AE39 -> 0.86116119 | AF40: =AF38/AF39 -> 0.87072451 | AG40: =AG38/AG39 -> 0.83803729 | AH40: =AH38/AH39 -> 0.87398938 | ... AM40: =AM38/AM39 -> 0.87990385
...

Sheet Y2
A1: Part | B1: Annual_Demand_Mean_Units | C1: Weekly_Demand_StdDev_Units | D1: Weekly_Robust_Demand_99p5_Units | E1: Total_Minutes_Per_Unit | F1: Weekly_Robust_Net_Minutes | G1: Weekly_Robust_Gross_Minutes | K1: Process Time | L1: A | M1: B | N1: C | O1: D | P1: E | Q1: F | R1: G | S1: H | T1: I | U1: J | V1: K | W1: L | X1: M | Z1: Distance | AA1: A | AB1: B | AC1: C | AD1: D | AE1: E | AF1: F | AG1: G | AH1: H | AI1: I | AJ1: J | AK1: K | AL1: L | AM1: M
A2: P1 | B2: 1357200 | C2: 1835.8084 | D2: 34466.075 | E2: 12.75 | F2: 393066.29 | G2: 498234.08 | K2: P1 | L2: 1 | M2: 5 | N2: 0.5 | O2: 2.5 | P2: 0 | Q2: 0 | R2: 0 | S2: 0 | T2: 1.25 | U2: 2.5 | V2: 0 | W2: 0 | X2: 0 | Z2: A | AA2: 0 | AB2: 146 | AC2: 311 | AD2: 0 | AE2: 0 | AF2: 0 | AG2: 0 | AH2: 0 | AI2: 0 | AJ2: 0 | AK2: 0 | AL2: 0 | AM2: 0
A3: P2 | B3: 800800 | C3: 1196.4692 | D3: 20163.7 | E3: 7.75 | F3: 143234.73 | G3: 177175.37 | K3: P2 | L3: 1.25 | M3: 0 | N3: 0.5 | O3: 2.5 | P3: 0 | Q3: 0 | R3: 0 | S3: 1 | T3: 0 | U3: 2.5 | V3: 0 | W3: 0 | X3: 0 | Z3: B | AA3: 146 | AB3: 0 | AC3: 165 | AD3: 357 | AE3: 0 | AF3: 0 | AG3: 0 | AH3: 0 | AI3: 0 | AJ3: 0 | AK3: 0 | AL3: 0 | AM3: 0
A4: P3 | B4: 655200 | C4: 920.28424 | D4: 9964.7 | E4: 9.5 | F4: 142219.7 | G4: 107329.54 | K4: P3 | L4: 0 | M4: 1.75 | N4: 0.75 | O4: 3 | P4: 0 | Q4: 0 | R4: 0 | S4: 0 | T4: 1.5 | U4: 2.5 | V4: 0 | W4: 0 | X4: 0 | Z4: C | AA4: 0 | AB4: 0 | AC4: 0 | AD4: 193 | AE4: 0 | AF4: 0 | AG4: 0 | AH4: 0 | AI4: =236+211 -> 447 | AJ4: 0 | AK4: 0 | AL4: 0 | AM4: 0
A5: P4 | B5: 530400 | C5: 887.95357 | D5: 14876.2 | E5: 7.5 | F5: 93654.126 | G5: 126498.3 | K5: P4 | L5: 1 | M5: 2 | N5: 0 | O5: 3 | P5: 0 | Q5: 0 | R5: 0.25 | S5: 1.25 | T5: 0 | U5: 0 | V5: 0 | W5: 0 | X5: 0 | Z5: D | AA5: 0 | AB5: 0 | AC5: 193 | AD5: 0 | AE5: 0 | AF5: 0 | AG5: 89 | AH5: =209+219 -> 428 | AI5: =428+209 -> 637 | AJ5: 0 | AK5: 0 | AL5: 0 | AM5: 0
A6: P5 | B6: 462800 | C6: 813.46836 | D6: 11211 | E6: 7.5 | F6: 82465.167 | G6: 95331.633 | K6: P5 | L6: 0 | M6: 1.5 | N6: 0.75 | O6: 3.5 | P6: 0 | Q6: 0 | R6: 0 | S6: 0 | T6: 1.75 | U6: 0 | V6: 0 | W6: 0 | X6: 0 | Z6: E | AA6: 0 | AB6: 0 | AC6: 0 | AD6: 0 | AE6: 0 | AF6: 282 | AG6: 485 | AH6: =633+131 -> 764 | AI6: 0 | AJ6: 0 | AK6: 0 | AL6: 0 | AM6: 0
A7: P6 | B7: 452400 | C7: 736.02362 | D7: 7347.975 | E7: 10.5 | F7: 111256.65 | G7: 87475.893 | K7: P6 | L7: 0.75 | M7: 1.25 | N7: 0.5 | O7: 3 | P7: 0 | Q7: 0 | R7: 0 | S7: 1 | T7: 1.25 | U7: 2.75 | V7: 0 | W7: 0 | X7: 0 | Z7: F | AA7: 0 | AB7: 0 | AC7: 89 | AD7: 0 | AE7: 0 | AF7: 0 | AG7: 202 | AH7: 350 | AI7: =287+123 -> 410 | AJ7: 0 | AK7: 0 | AL7: 0 | AM7: 0
A8: P7 | B8: 878800 | C8: 1503.3936 | D8: 22657.2 | E8: 10 | F8: 207724.85 | G8: 256884.35 | K8: P7 | L8: 0 | M8: 0 | N8: 0.75 | O8: 3.5 | P8: 1 | Q8: 1.5 | R8: 0 | S8: 0 | T8: 1.25 | U8: 2 | V8: 0 | W8: 0 | X8: 0 | Z8: G | AA8: 0 | AB8: 0 | AC8: 0 | AD8: 0 | AE8: =489 -> 489 | AF8: 202 | AG8: 0 | AH8: =148+131 -> 279 | AI8: =489+121 -> 610 | AJ8: 0 | AK8: 0 | AL8: 0 | AM8: 0
A9: P8 | B9: 634400 | C9: 973.8899 | D9: 7330.4 | E9: 4.75 | F9: 69865.727 | G9: 39477.778 | K9: P8 | L9: 0 | M9: 0 | N9: 0 | O9: 0 | P9: 1.25 | Q9: 0 | R9: 0 | S9: 2 | T9: 1 | U9: 0.5 | V9: 0 | W9: 0 | X9: 0 | Z9: H | AA9: 0 | AB9: 0 | AC9: 0 | AD9: 0 | AE9: 0 | AF9: 0 | AG9: 0 | AH9: 0 | AI9: =636 -> 636 | AJ9: =317 -> 317 | AK9: 0 | AL9: 0 | AM9: 0
A10: P9 | B10: 592800 | C10: 952.32509 | D10: 14241 | E10: 8.5 | F10: 117750.73 | G10: 137243.2 | K10: P9 | L10: 0 | M10: 0 | N10: 0 | O10: 0 | P10: 1.25 | Q10: 1.75 | R10: 1.25 | S10: 0 | T10: 1.25 | U10: 3 | V10: 0 | W10: 0 | X10: 0 | Z10: I | AA10: 0 | AB10: 0 | AC10: 0 | AD10: 0 | AE10: 0 | AF10: 0 | AG10: 0 | AH10: 0 | AI10: 0 | AJ10: =319 -> 319 | AK10: 0 | AL10: 0 | AM10: 0
A11: P10 | B11: 353600 | C11: 498.84482 | D11: 8002.475 | E11: 6.5 | F11: 52552.104 | G11: 58975.156 | K11: P10 | L11: 0 | M11: 0 | N11: 0 | O11: 0 | P11: 1.5 | Q11: 1.75 | R11: 0 | S11: 0 | T11: 1.25 | U11: 2 | V11: 0 | W11: 0 | X11: 0 | Z11: J | AA11: 0 | AB11: 0 | AC11: 0 | AD11: 0 | AE11: 0 | AF11: 0 | AG11: 0 | AH11: 0 | AI11: 319 | AJ11: 0 | AK11: 0 | AL11: 0 | AM11: 0
A12: P11 | B12: 790400 | C12: 1223.4881 | D12: 14695.95 | E12: 4 | F12: 73405.986 | G12: 66648.299 | K12: P11 | L12: 0 | M12: 0 | N12: 0 | O12: 0 | P12: 2.5 | Q12: 0 | R12: 0.75 | S12: 0 | T12: 0.75 | U12: 0 | V12: 0 | W12: 0 | X12: 0 | Z12: K | AA12: 0 | AB12: 0 | AC12: 0 | AD12: 0 | AE12: 0 | AF12: 0 | AG12: 0 | AH12: 0 | AI12: 0 | AJ12: 0 | AK12: 0 | AL12: 85.5 | AM12: 95
A13: P12 | B13: 946400 | C13: 1392.5627 | D13: 18854.7 | E13: 6 | F13: 130722.02 | G13: 128263.27 | K13: P12 | L13: 0 | M13: 0 | N13: 0 | O13: 0 | P13: 1 | Q13: 1 | R13: 0.5 | S13: 0 | T13: 1.25 | U13: 2.25 | V13: 0 | W13: 0 | X13: 0 | Z13: L | AA13: 0 | AB13: 0 | AC13: 0 | AD13: 0 | AE13: 0 | AF13: 0 | AG13: 0 | AH13: 0 | AI13: 0 | AJ13: 0 | AK13: 85.5 | AL13: 0 | AM13: =85.5+95 -> 180.5
A14: P13 | B14: 473200 | C14: 709.95666 | D14: 9427.35 | E14: 7.5 | F14: 81965.454 | G14: 80164.541 | K14: P13 | L14: 0 | M14: 0 | N14: 0 | O14: 0 | P14: 1.25 | Q14: 2.25 | R14: 0.75 | S14: 2 | T14: 1.25 | U14: 0 | V14: 0 | W14: 0 | X14: 0 | Z14: M | AA14: 0 | AB14: 0 | AC14: 0 | AD14: 0 | AE14: 0 | AF14: 0 | AG14: 0 | AH14: 0 | AI14: 0 | AJ14: 0 | AK14: 0 | AL14: =180.5 -> 180.5 | AM14: 0
A15: P14 | B15: 1279200 | C15: 1623.1498 | D15: 29234.8 | E15: 4.75 | F15: 136709.55 | G15: 157443.65 | K15: P14 | L15: 0 | M15: 0 | N15: 0 | O15: 0 | P15: 1 | Q15: 1.5 | R15: 0.5 | S15: 1.75 | T15: 0 | U15: 0 | V15: 0 | W15: 0 | X15: 0
A16: P15 | B16: 312000 | C16: 505.35593 | D16: 3665.2 | E16: 7.5 | F16: 54762.83 | G16: 31166.667 | K16: P15 | L16: 0 | M16: 0 | N16: 0 | O16: 0 | P16: 0.75 | Q16: 1.25 | R16: 0.5 | S16: 2.5 | T16: 0 | U16: 2.5 | V16: 0 | W16: 0 | X16: 0
A17: P16 | B17: 665600 | C17: 1523.1546 | D17: 19392 | E17: 10 | F17: 167233.86 | G17: 219863.95 | K17: P16 | L17: 0 | M17: 0 | N17: 0 | O17: 0 | P17: 0 | Q17: 1.25 | R17: 0 | S17: 5 | T17: 1.25 | U17: 2.5 | V17: 0 | W17: 0 | X17: 0 | Z17: Capacity | AA17: A | AB17: B | AC17: C | AD17: D | AE17: E | AF17: F | AG17: G | AH17: H | AI17: I | AJ17: J | AK17: K | AL17: L | AM17: M
A18: P17 | B18: 561600 | C18: 739.02222 | D18: 9427.35 | E18: 7.25 | F18: 92101.064 | G18: 77492.389 | K18: P17 | L18: 0 | M18: 0 | N18: 0 | O18: 0 | P18: 0 | Q18: 0 | R18: 0 | S18: 0 | T18: 0 | U18: 0 | V18: 0.75 | W18: 3 | X18: 3.5 | Z18: P1 | AA18: =L2*$D$2 -> 34466.075 | AB18: =M2*$D$2 -> 172330.38 | AC18: =N2*$D$2 -> 17233.037 | AD18: =O2*$D$2 -> 86165.188 | AE18: =P2*$D$2 -> 0 | AF18: =Q2*$D$2 -> 0 | AG18: =R2*$D$2 -> 0 | AH18: =S2*$D$2 -> 0 | ... AM18: =X2*$D$2 -> 0
A19: P18 | B19: 920400 | C19: 1352.2773 | D19: 21884.7 | E19: 6.25 | F19: 132395.22 | G19: 155078.66 | K19: P18 | L19: 0 | M19: 0 | N19: 0 | O19: 0 | P19: 0 | Q19: 0 | R19: 0 | S19: 0 | T19: 0 | U19: 0 | V19: 1.25 | W19: 1.25 | X19: 3.75 | Z19: P2 | AA19: =L3*$D$3 -> 25204.625 | AB19: =M3*$D$3 -> 0 | AC19: =N3*$D$3 -> 10081.85 | AD19: =O3*$D$3 -> 50409.25 | AE19: =P3*$D$3 -> 0 | AF19: =Q3*$D$3 -> 0 | AG19: =R3*$D$3 -> 0 | AH19: =S3*$D$3 -> 20163.7 | ... AM19: =X3*$D$3 -> 0
A20: P19 | B20: 1341600 | C20: 1861.5544 | D20: 32386.7 | E20: 10.5 | F20: 321247.99 | G20: 385555.95 | K20: P19 | L20: 0 | M20: 0 | N20: 0 | O20: 0 | P20: 0 | Q20: 0 | R20: 0 | S20: 0 | T20: 0 | U20: 0 | V20: 0 | W20: 4.25 | X20: 6.25 | Z20: P3 | AA20: =L4*$D$4 -> 0 | AB20: =M4*$D$4 -> 17438.225 | AC20: =N4*$D$4 -> 7473.525 | AD20: =O4*$D$4 -> 29894.1 | AE20: =P4*$D$4 -> 0 | AF20: =Q4*$D$4 -> 0 | AG20: =R4*$D$4 -> 0 | AH20: =S4*$D$4 -> 0 | ... AM20: =X4*$D$4 -> 0
A21: P20 | B21: 1097200 | C21: 1533.5354 | D21: 23829.3 | E21: 5.75 | F21: 144038.22 | G21: 155349.74 | K21: P20 | L21: 0 | M21: 0 | N21: 0 | O21: 0 | P21: 0 | Q21: 0 | R21: 0 | S21: 0 | T21: 0 | U21: 0 | V21: 0.75 | W21: 2 | X21: 3 | Z21: P4 | AA21: =L5*$D$5 -> 14876.2 | AB21: =M5*$D$5 -> 29752.4 | AC21: =N5*$D$5 -> 0 | AD21: =O5*$D$5 -> 44628.6 | AE21: =P5*$D$5 -> 0 | AF21: =Q5*$D$5 -> 0 | AG21: =R5*$D$5 -> 3719.05 | AH21: =S5*$D$5 -> 18595.25 | ... AM21: =X5*$D$5 -> 0
D22: =SUM(D2:D21) -> 333058.78 | Z22: P5 | AA22: =L6*$D$6 -> 0 | AB22: =M6*$D$6 -> 16816.5 | AC22: =N6*$D$6 -> 8408.25 | AD22: =O6*$D$6 -> 39238.5 | AE22: =P6*$D$6 -> 0 | AF22: =Q6*$D$6 -> 0 | AG22: =R6*$D$6 -> 0 | AH22: =S6*$D$6 -> 0 | ... AM22: =X6*$D$6 -> 0
Z23: P6 | AA23: =L7*$D$7 -> 5510.9813 | AB23: =M7*$D$7 -> 9184.9688 | AC23: =N7*$D$7 -> 3673.9875 | AD23: =O7*$D$7 -> 22043.925 | AE23: =P7*$D$7 -> 0 | AF23: =Q7*$D$7 -> 0 | AG23: =R7*$D$7 -> 0 | AH23: =S7*$D$7 -> 7347.975 | ... AM23: =X7*$D$7 -> 0
K24: Proportion | L24: A | M24: B | N24: C | O24: D | P24: E | Q24: F | R24: G | S24: H | T24: I | U24: J | V24: K | W24: L | X24: M | Z24: P7 | AA24: =L8*$D$8 -> 0 | AB24: =M8*$D$8 -> 0 | AC24: =N8*$D$8 -> 16992.9 | AD24: =O8*$D$8 -> 79300.2 | AE24: =P8*$D$8 -> 22657.2 | AF24: =Q8*$D$8 -> 33985.8 | AG24: =R8*$D$8 -> 0 | AH24: =S8*$D$8 -> 0 | ... AM24: =X8*$D$8 -> 0
K25: P1 | L25: =L2/$E$2 -> 0.078431373 | M25: =M2/$E$2 -> 0.39215686 | N25: =N2/$E$2 -> 0.039215686 | O25: =O2/$E$2 -> 0.19607843 | P25: =P2/$E$2 -> 0 | Q25: =Q2/$E$2 -> 0 | R25: =R2/$E$2 -> 0 | S25: =S2/$E$2 -> 0 | ... X25: =X2/$E$2 -> 0 | Z25: P8 | AA25: =L9*$D$9 -> 0 | AB25: =M9*$D$9 -> 0 | AC25: =N9*$D$9 -> 0 | AD25: =O9*$D$9 -> 0 | AE25: =P9*$D$9 -> 9163 | AF25: =Q9*$D$9 -> 0 | AG25: =R9*$D$9 -> 0 | AH25: =S9*$D$9 -> 14660.8 | ... AM25: =X9*$D$9 -> 0
K26: P2 | L26: =L3/$E$3 -> 0.16129032 | M26: =M3/$E$3 -> 0 | N26: =N3/$E$3 -> 0.064516129 | O26: =O3/$E$3 -> 0.32258065 | P26: =P3/$E$3 -> 0 | Q26: =Q3/$E$3 -> 0 | R26: =R3/$E$3 -> 0 | S26: =S3/$E$3 -> 0.12903226 | ... X26: =X3/$E$3 -> 0 | Z26: P9 | AA26: =L10*$D$10 -> 0 | AB26: =M10*$D$10 -> 0 | AC26: =N10*$D$10 -> 0 | AD26: =O10*$D$10 -> 0 | AE26: =P10*$D$10 -> 17801.25 | AF26: =Q10*$D$10 -> 24921.75 | AG26: =R10*$D$10 -> 17801.25 | AH26: =S10*$D$10 -> 0 | ... AM26: =X10*$D$10 -> 0
K27: P3 | L27: =L4/$E$4 -> 0 | M27: =M4/$E$4 -> 0.18421053 | N27: =N4/$E$4 -> 0.078947368 | O27: =O4/$E$4 -> 0.31578947 | P27: =P4/$E$4 -> 0 | Q27: =Q4/$E$4 -> 0 | R27: =R4/$E$4 -> 0 | S27: =S4/$E$4 -> 0 | ... X27: =X4/$E$4 -> 0 | Z27: P10 | AA27: =L11*$D$11 -> 0 | AB27: =M11*$D$11 -> 0 | AC27: =N11*$D$11 -> 0 | AD27: =O11*$D$11 -> 0 | AE27: =P11*$D$11 -> 12003.713 | AF27: =Q11*$D$11 -> 14004.331 | AG27: =R11*$D$11 -> 0 | AH27: =S11*$D$11 -> 0 | ... AM27: =X11*$D$11 -> 0
K28: P4 | L28: =L5/$E$5 -> 0.13333333 | M28: =M5/$E$5 -> 0.26666667 | N28: =N5/$E$5 -> 0 | O28: =O5/$E$5 -> 0.4 | P28: =P5/$E$5 -> 0 | Q28: =Q5/$E$5 -> 0 | R28: =R5/$E$5 -> 0.033333333 | S28: =S5/$E$5 -> 0.16666667 | ... X28: =X5/$E$5 -> 0 | Z28: P11 | AA28: =L12*$D$12 -> 0 | AB28: =M12*$D$12 -> 0 | AC28: =N12*$D$12 -> 0 | AD28: =O12*$D$12 -> 0 | AE28: =P12*$D$12 -> 36739.875 | AF28: =Q12*$D$12 -> 0 | AG28: =R12*$D$12 -> 11021.963 | AH28: =S12*$D$12 -> 0 | ... AM28: =X12*$D$12 -> 0
K29: P5 | L29: =L6/$E$6 -> 0 | M29: =M6/$E$6 -> 0.2 | N29: =N6/$E$6 -> 0.1 | O29: =O6/$E$6 -> 0.46666667 | P29: =P6/$E$6 -> 0 | Q29: =Q6/$E$6 -> 0 | R29: =R6/$E$6 -> 0 | S29: =S6/$E$6 -> 0 | ... X29: =X6/$E$6 -> 0 | Z29: P12 | AA29: =L13*$D$13 -> 0 | AB29: =M13*$D$13 -> 0 | AC29: =N13*$D$13 -> 0 | AD29: =O13*$D$13 -> 0 | AE29: =P13*$D$13 -> 18854.7 | AF29: =Q13*$D$13 -> 18854.7 | AG29: =R13*$D$13 -> 9427.35 | AH29: =S13*$D$13 -> 0 | ... AM29: =X13*$D$13 -> 0
K30: P6 | L30: =L7/$E$7 -> 0.071428571 | M30: =M7/$E$7 -> 0.11904762 | N30: =N7/$E$7 -> 0.047619048 | O30: =O7/$E$7 -> 0.28571429 | P30: =P7/$E$7 -> 0 | Q30: =Q7/$E$7 -> 0 | R30: =R7/$E$7 -> 0 | S30: =S7/$E$7 -> 0.095238095 | ... X30: =X7/$E$7 -> 0 | Z30: P13 | AA30: =L14*$D$14 -> 0 | AB30: =M14*$D$14 -> 0 | AC30: =N14*$D$14 -> 0 | AD30: =O14*$D$14 -> 0 | AE30: =P14*$D$14 -> 11784.188 | AF30: =Q14*$D$14 -> 21211.538 | AG30: =R14*$D$14 -> 7070.5125 | AH30: =S14*$D$14 -> 18854.7 | ... AM30: =X14*$D$14 -> 0
K31: P7 | L31: =L8/$E$8 -> 0 | M31: =M8/$E$8 -> 0 | N31: =N8/$E$8 -> 0.075 | O31: =O8/$E$8 -> 0.35 | P31: =P8/$E$8 -> 0.1 | Q31: =Q8/$E$8 -> 0.15 | R31: =R8/$E$8 -> 0 | S31: =S8/$E$8 -> 0 | ... X31: =X8/$E$8 -> 0 | Z31: P14 | AA31: =L15*$D$15 -> 0 | AB31: =M15*$D$15 -> 0 | AC31: =N15*$D$15 -> 0 | AD31: =O15*$D$15 -> 0 | AE31: =P15*$D$15 -> 29234.8 | AF31: =Q15*$D$15 -> 43852.2 | AG31: =R15*$D$15 -> 14617.4 | AH31: =S15*$D$15 -> 51160.9 | ... AM31: =X15*$D$15 -> 0
K32: P8 | L32: =L9/$E$9 -> 0 | M32: =M9/$E$9 -> 0 | N32: =N9/$E$9 -> 0 | O32: =O9/$E$9 -> 0 | P32: =P9/$E$9 -> 0.26315789 | Q32: =Q9/$E$9 -> 0 | R32: =R9/$E$9 -> 0 | S32: =S9/$E$9 -> 0.42105263 | ... X32: =X9/$E$9 -> 0 | Z32: P15 | AA32: =L16*$D$16 -> 0 | AB32: =M16*$D$16 -> 0 | AC32: =N16*$D$16 -> 0 | AD32: =O16*$D$16 -> 0 | AE32: =P16*$D$16 -> 2748.9 | AF32: =Q16*$D$16 -> 4581.5 | AG32: =R16*$D$16 -> 1832.6 | AH32: =S16*$D$16 -> 9163 | ... AM32: =X16*$D$16 -> 0
K33: P9 | L33: =L10/$E$10 -> 0 | M33: =M10/$E$10 -> 0 | N33: =N10/$E$10 -> 0 | O33: =O10/$E$10 -> 0 | P33: =P10/$E$10 -> 0.14705882 | Q33: =Q10/$E$10 -> 0.20588235 | R33: =R10/$E$10 -> 0.14705882 | S33: =S10/$E$10 -> 0 | ... X33: =X10/$E$10 -> 0 | Z33: P16 | AA33: =L17*$D$17 -> 0 | AB33: =M17*$D$17 -> 0 | AC33: =N17*$D$17 -> 0 | AD33: =O17*$D$17 -> 0 | AE33: =P17*$D$17 -> 0 | AF33: =Q17*$D$17 -> 24240 | AG33: =R17*$D$17 -> 0 | AH33: =S17*$D$17 -> 96960 | ... AM33: =X17*$D$17 -> 0
K34: P10 | L34: =L11/$E$11 -> 0 | M34: =M11/$E$11 -> 0 | N34: =N11/$E$11 -> 0 | O34: =O11/$E$11 -> 0 | P34: =P11/$E$11 -> 0.23076923 | Q34: =Q11/$E$11 -> 0.26923077 | R34: =R11/$E$11 -> 0 | S34: =S11/$E$11 -> 0 | ... X34: =X11/$E$11 -> 0 | Z34: P17 | AA34: =L18*$D$18 -> 0 | AB34: =M18*$D$18 -> 0 | AC34: =N18*$D$18 -> 0 | AD34: =O18*$D$18 -> 0 | AE34: =P18*$D$18 -> 0 | AF34: =Q18*$D$18 -> 0 | AG34: =R18*$D$18 -> 0 | AH34: =S18*$D$18 -> 0 | ... AM34: =X18*$D$18 -> 32995.725
K35: P11 | L35: =L12/$E$12 -> 0 | M35: =M12/$E$12 -> 0 | N35: =N12/$E$12 -> 0 | O35: =O12/$E$12 -> 0 | P35: =P12/$E$12 -> 0.625 | Q35: =Q12/$E$12 -> 0 | R35: =R12/$E$12 -> 0.1875 | S35: =S12/$E$12 -> 0 | ... X35: =X12/$E$12 -> 0 | Z35: P18 | AA35: =L19*$D$19 -> 0 | AB35: =M19*$D$19 -> 0 | AC35: =N19*$D$19 -> 0 | AD35: =O19*$D$19 -> 0 | AE35: =P19*$D$19 -> 0 | AF35: =Q19*$D$19 -> 0 | AG35: =R19*$D$19 -> 0 | AH35: =S19*$D$19 -> 0 | ... AM35: =X19*$D$19 -> 82067.625
K36: P12 | L36: =L13/$E$13 -> 0 | M36: =M13/$E$13 -> 0 | N36: =N13/$E$13 -> 0 | O36: =O13/$E$13 -> 0 | P36: =P13/$E$13 -> 0.16666667 | Q36: =Q13/$E$13 -> 0.16666667 | R36: =R13/$E$13 -> 0.083333333 | S36: =S13/$E$13 -> 0 | ... X36: =X13/$E$13 -> 0 | Z36: P19 | AA36: =L20*$D$20 -> 0 | AB36: =M20*$D$20 -> 0 | AC36: =N20*$D$20 -> 0 | AD36: =O20*$D$20 -> 0 | AE36: =P20*$D$20 -> 0 | AF36: =Q20*$D$20 -> 0 | AG36: =R20*$D$20 -> 0 | AH36: =S20*$D$20 -> 0 | ... AM36: =X20*$D$20 -> 202416.88
K37: P13 | L37: =L14/$E$14 -> 0 | M37: =M14/$E$14 -> 0 | N37: =N14/$E$14 -> 0 | O37: =O14/$E$14 -> 0 | P37: =P14/$E$14 -> 0.16666667 | Q37: =Q14/$E$14 -> 0.3 | R37: =R14/$E$14 -> 0.1 | S37: =S14/$E$14 -> 0.26666667 | ... X37: =X14/$E$14 -> 0 | Z37: P20 | AA37: =L21*$D$21 -> 0 | AB37: =M21*$D$21 -> 0 | AC37: =N21*$D$21 -> 0 | AD37: =O21*$D$21 -> 0 | AE37: =P21*$D$21 -> 0 | AF37: =Q21*$D$21 -> 0 | AG37: =R21*$D$21 -> 0 | AH37: =S21*$D$21 -> 0 | ... AM37: =X21*$D$21 -> 71487.9
K38: P14 | L38: =L15/$E$15 -> 0 | M38: =M15/$E$15 -> 0 | N38: =N15/$E$15 -> 0 | O38: =O15/$E$15 -> 0 | P38: =P15/$E$15 -> 0.21052632 | Q38: =Q15/$E$15 -> 0.31578947 | R38: =R15/$E$15 -> 0.10526316 | S38: =S15/$E$15 -> 0.36842105 | ... X38: =X15/$E$15 -> 0 | Z38: Sum | AA38: =SUM(AA18:AA37) -> 80057.881 | AB38: =SUM(AB18:AB37) -> 245522.47 | AC38: =SUM(AC18:AC37) -> 63863.55 | AD38: =SUM(AD18:AD37) -> 351679.76 | AE38: =SUM(AE18:AE37) -> 160987.62 | AF38: =SUM(AF18:AF37) -> 185651.82 | AG38: =SUM(AG18:AG37) -> 65490.125 | AH38: =SUM(AH18:AH37) -> 236906.32 | ... AM38: =SUM(AM18:AM37) -> 388968.12
K39: P15 | L39: =L16/$E$16 -> 0 | M39: =M16/$E$16 -> 0 | N39: =N16/$E$16 -> 0 | O39: =O16/$E$16 -> 0 | P39: =P16/$E$16 -> 0.1 | Q39: =Q16/$E$16 -> 0.16666667 | R39: =R16/$E$16 -> 0.066666667 | S39: =S16/$E$16 -> 0.33333333 | ... X39: =X16/$E$16 -> 0 | Z39: Sum Capacity | AA39: =5*16*60*L78 -> 91200 | AB39: =5*16*60*M78 -> 278400 | AC39: =5*16*60*N78 -> 76800 | AD39: =5*16*60*O78 -> 403200 | AE39: =5*16*60*P78 -> 187200 | AF39: =5*16*60*Q78 -> 211200 | AG39: =5*16*60*R78 -> 76800 | AH39: =5*16*60*S78 -> 268800 | ... AM39: =5*16*60*X78 -> 441600
K40: P16 | L40: =L17/$E$17 -> 0 | M40: =M17/$E$17 -> 0 | N40: =N17/$E$17 -> 0 | O40: =O17/$E$17 -> 0 | P40: =P17/$E$17 -> 0 | Q40: =Q17/$E$17 -> 0.125 | R40: =R17/$E$17 -> 0 | S40: =S17/$E$17 -> 0.5 | ... X40: =X17/$E$17 -> 0 | Z40: Utilization | AA40: =AA38/AA39 -> 0.87782765 | AB40: =AB38/AB39 -> 0.88190542 | AC40: =AC38/AC39 -> 0.83155664 | AD40: =AD38/AD39 -> 0.87222163 | AE40: =AE38/AE39 -> 0.85997663 | AF40: =AF38/AF39 -> 0.87903323 | AG40: =AG38/AG39 -> 0.852736 | AH40: =AH38/AH39 -> 0.88134794 | ... AM40: =AM38/AM39 -> 0.8808155
...

Sheet Y3
A1: Part | B1: Annual_Demand_Mean_Units | C1: Weekly_Demand_StdDev_Units | D1: Weekly_Robust_Demand_99p5_Units | E1: Total_Minutes_Per_Unit | F1: Weekly_Robust_Net_Minutes | G1: Weekly_Robust_Gross_Minutes | K1: Time | L1: A | M1: B | N1: C | O1: D | P1: E | Q1: F | R1: G | S1: H | T1: I | U1: J | V1: K | W1: L | X1: M | Z1: Distance | AA1: A | AB1: B | AC1: C | AD1: D | AE1: E | AF1: F | AG1: G | AH1: H | AI1: I | AJ1: J | AK1: K | AL1: L | AM1: M
A2: P1 | B2: 1419600 | C2: 1958.0701 | D2: 35233.45 | E2: 12.75 | F2: 412381.59 | G2: 509327.08 | K2: P1 | L2: 1 | M2: 5 | N2: 0.5 | O2: 2.5 | P2: 0 | Q2: 0 | R2: 0 | S2: 0 | T2: 1.25 | U2: 2.5 | V2: 0 | W2: 0 | X2: 0 | Z2: A | AA2: 0 | AB2: 146 | AC2: 311 | AD2: 0 | AE2: 0 | AF2: 0 | AG2: 0 | AH2: 0 | AI2: 0 | AJ2: 0 | AK2: 0 | AL2: 0 | AM2: 0
A3: P2 | B3: 795600 | C3: 1153.3396 | D3: 19629.8 | E3: 7.75 | F3: 141598.75 | G3: 172484.07 | K3: P2 | L3: 1.25 | M3: 0 | N3: 0.5 | O3: 2.5 | P3: 0 | Q3: 0 | R3: 0 | S3: 1 | T3: 0 | U3: 2.5 | V3: 0 | W3: 0 | X3: 0 | Z3: B | AA3: 146 | AB3: 0 | AC3: 165 | AD3: 357 | AE3: 0 | AF3: 0 | AG3: 0 | AH3: 0 | AI3: 0 | AJ3: 0 | AK3: 0 | AL3: 0 | AM3: 0
A4: P3 | B4: 884000 | C4: 1181.7523 | D4: 11450.95 | E4: 9.5 | F4: 190417.93 | G4: 123337.9 | K4: P3 | L4: 0 | M4: 1.75 | N4: 0.75 | O4: 3 | P4: 0 | Q4: 0 | R4: 0 | S4: 0 | T4: 1.5 | U4: 2.5 | V4: 0 | W4: 0 | X4: 0 | Z4: C | AA4: 0 | AB4: 0 | AC4: 0 | AD4: 193 | AE4: 0 | AF4: 0 | AG4: 0 | AH4: 0 | AI4: =236+211 -> 447 | AJ4: 0 | AK4: 0 | AL4: 0 | AM4: 0
A5: P4 | B5: 546000 | C5: 941.86803 | D5: 15248.3 | E5: 7.5 | F5: 96945.685 | G5: 129662.41 | K5: P4 | L5: 1 | M5: 2 | N5: 0 | O5: 3 | P5: 0 | Q5: 0 | R5: 0.25 | S5: 1.25 | T5: 0 | U5: 0 | V5: 0 | W5: 0 | X5: 0 | Z5: D | AA5: 0 | AB5: 0 | AC5: 193 | AD5: 0 | AE5: 0 | AF5: 0 | AG5: 89 | AH5: =209+219 -> 428 | AI5: =428+209 -> 637 | AJ5: 0 | AK5: 0 | AL5: 0 | AM5: 0
A6: P5 | B6: 509600 | C6: 867.57842 | D6: 11059.5 | E6: 7.5 | F6: 90260.504 | G6: 94043.367 | K6: P5 | L6: 0 | M6: 1.5 | N6: 0.75 | O6: 3.5 | P6: 0 | Q6: 0 | R6: 0 | S6: 0 | T6: 1.75 | U6: 0 | V6: 0 | W6: 0 | X6: 0 | Z6: E | AA6: 0 | AB6: 0 | AC6: 0 | AD6: 0 | AE6: 0 | AF6: 282 | AG6: 485 | AH6: =633+131 -> 764 | AI6: 0 | AJ6: 0 | AK6: 0 | AL6: 0 | AM6: 0
A7: P6 | B7: 514800 | C7: 869.68164 | D7: 7810.2 | E7: 10.5 | F7: 127471.59 | G7: 92978.571 | K7: P6 | L7: 0.75 | M7: 1.25 | N7: 0.5 | O7: 3 | P7: 0 | Q7: 0 | R7: 0 | S7: 1 | T7: 1.25 | U7: 2.75 | V7: 0 | W7: 0 | X7: 0 | Z7: F | AA7: 0 | AB7: 0 | AC7: 89 | AD7: 0 | AE7: 0 | AF7: 0 | AG7: 202 | AH7: 350 | AI7: =287+123 -> 410 | AJ7: 0 | AK7: 0 | AL7: 0 | AM7: 0
A8: P7 | B8: 878800 | C8: 1453.1795 | D8: 21383.4 | E8: 10 | F8: 206431.42 | G8: 242442.18 | K8: P7 | L8: 0 | M8: 0 | N8: 0.75 | O8: 3.5 | P8: 1 | Q8: 1.5 | R8: 0 | S8: 0 | T8: 1.25 | U8: 2 | V8: 0 | W8: 0 | X8: 0 | Z8: G | AA8: 0 | AB8: 0 | AC8: 0 | AD8: 0 | AE8: =489 -> 489 | AF8: 202 | AG8: 0 | AH8: =148+131 -> 279 | AI8: =489+121 -> 610 | AJ8: 0 | AK8: 0 | AL8: 0 | AM8: 0
A9: P8 | B9: 826800 | C9: 1194.6193 | D9: 8377.6 | E9: 4.75 | F9: 90141.394 | G9: 45117.46 | K9: P8 | L9: 0 | M9: 0 | N9: 0 | O9: 0 | P9: 1.25 | Q9: 0 | R9: 0 | S9: 2 | T9: 1 | U9: 0.5 | V9: 0 | W9: 0 | X9: 0 | Z9: H | AA9: 0 | AB9: 0 | AC9: 0 | AD9: 0 | AE9: 0 | AF9: 0 | AG9: 0 | AH9: 0 | AI9: =636 -> 636 | AJ9: =317 -> 317 | AK9: 0 | AL9: 0 | AM9: 0
A10: P9 | B10: 639600 | C10: 969.63514 | D10: 13332 | E10: 8.5 | F10: 125779.72 | G10: 128482.99 | K10: P9 | L10: 0 | M10: 0 | N10: 0 | O10: 0 | P10: 1.25 | Q10: 1.75 | R10: 1.25 | S10: 0 | T10: 1.25 | U10: 3 | V10: 0 | W10: 0 | X10: 0 | Z10: I | AA10: 0 | AB10: 0 | AC10: 0 | AD10: 0 | AE10: 0 | AF10: 0 | AG10: 0 | AH10: 0 | AI10: 0 | AJ10: =319 -> 319 | AK10: 0 | AL10: 0 | AM10: 0
A11: P10 | B11: 374400 | C11: 530.96429 | D11: 8151.4 | E11: 6.5 | F11: 55689.877 | G11: 60072.676 | K11: P10 | L11: 0 | M11: 0 | N11: 0 | O11: 0 | P11: 1.5 | Q11: 1.75 | R11: 0 | S11: 0 | T11: 1.25 | U11: 2 | V11: 0 | W11: 0 | X11: 0 | Z11: J | AA11: 0 | AB11: 0 | AC11: 0 | AD11: 0 | AE11: 0 | AF11: 0 | AG11: 0 | AH11: 0 | AI11: 319 | AJ11: 0 | AK11: 0 | AL11: 0 | AM11: 0
A12: P11 | B12: 977600 | C12: 1495.6347 | D12: 15620.4 | E12: 4 | F12: 90609.998 | G12: 70840.816 | K12: P11 | L12: 0 | M12: 0 | N12: 0 | O12: 0 | P12: 2.5 | Q12: 0 | R12: 0.75 | S12: 0 | T12: 0.75 | U12: 0 | V12: 0 | W12: 0 | X12: 0 | Z12: K | AA12: 0 | AB12: 0 | AC12: 0 | AD12: 0 | AE12: 0 | AF12: 0 | AG12: 0 | AH12: 0 | AI12: 0 | AJ12: 0 | AK12: 0 | AL12: 85.5 | AM12: 95
A13: P12 | B13: 1128400 | C13: 1580.2264 | D13: 18947.4 | E13: 6 | F13: 154622.36 | G13: 128893.88 | K13: P12 | L13: 0 | M13: 0 | N13: 0 | O13: 0 | P13: 1 | Q13: 1 | R13: 0.5 | S13: 0 | T13: 1.25 | U13: 2.25 | V13: 0 | W13: 0 | X13: 0 | Z13: L | AA13: 0 | AB13: 0 | AC13: 0 | AD13: 0 | AE13: 0 | AF13: 0 | AG13: 0 | AH13: 0 | AI13: 0 | AJ13: 0 | AK13: 85.5 | AL13: 0 | AM13: =85.5+95 -> 180.5
A14: P13 | B14: 551200 | C14: 801.44101 | D14: 9473.7 | E14: 7.5 | F14: 94982.814 | G14: 80558.673 | K14: P13 | L14: 0 | M14: 0 | N14: 0 | O14: 0 | P14: 1.25 | Q14: 2.25 | R14: 0.75 | S14: 2 | T14: 1.25 | U14: 0 | V14: 0 | W14: 0 | X14: 0 | Z14: M | AA14: 0 | AB14: 0 | AC14: 0 | AD14: 0 | AE14: 0 | AF14: 0 | AG14: 0 | AH14: 0 | AI14: 0 | AJ14: 0 | AK14: 0 | AL14: =180.5 -> 180.5 | AM14: 0
A15: P14 | B15: 1310400 | C15: 1602.402 | D15: 28212.5 | E15: 4.75 | F15: 139305.69 | G15: 151938.07 | K15: P14 | L15: 0 | M15: 0 | N15: 0 | O15: 0 | P15: 1 | Q15: 1.5 | R15: 0.5 | S15: 1.75 | T15: 0 | U15: 0 | V15: 0 | W15: 0 | X15: 0
A16: P15 | B16: 400400 | C16: 642.8602 | D16: 4188.8 | E16: 7.5 | F16: 70169.236 | G16: 35619.048 | K16: P15 | L16: 0 | M16: 0 | N16: 0 | O16: 0 | P16: 0.75 | Q16: 1.25 | R16: 0.5 | S16: 2.5 | T16: 0 | U16: 2.5 | V16: 0 | W16: 0 | X16: 0
A17: P16 | B17: 681200 | C17: 1622.0239 | D17: 19846.5 | E17: 10 | F17: 172780.57 | G17: 225017.01 | K17: P16 | L17: 0 | M17: 0 | N17: 0 | O17: 0 | P17: 0 | Q17: 1.25 | R17: 0 | S17: 5 | T17: 1.25 | U17: 2.5 | V17: 0 | W17: 0 | X17: 0 | Z17: Capacity | AA17: A | AB17: B | AC17: C | AD17: D | AE17: E | AF17: F | AG17: G | AH17: H | AI17: I | AJ17: J | AK17: K | AL17: L | AM17: M
A18: P17 | B18: 681200 | C18: 862.13063 | D18: 9473.7 | E18: 7.25 | F18: 111075.08 | G18: 77873.384 | K18: P17 | L18: 0 | M18: 0 | N18: 0 | O18: 0 | P18: 0 | Q18: 0 | R18: 0 | S18: 0 | T18: 0 | U18: 0 | V18: 0.75 | W18: 3 | X18: 3.5 | Z18: P1 | AA18: =L2*$D$2 -> 35233.45 | AB18: =M2*$D$2 -> 176167.25 | AC18: =N2*$D$2 -> 17616.725 | AD18: =O2*$D$2 -> 88083.625 | AE18: =P2*$D$2 -> 0 | AF18: =Q2*$D$2 -> 0 | AG18: =R2*$D$2 -> 0 | AH18: =S2*$D$2 -> 0 | ... AM18: =X2*$D$2 -> 0
A19: P18 | B19: 998400 | C19: 1435.136 | D19: 21219.9 | E19: 6.25 | F19: 143104.16 | G19: 150367.77 | K19: P18 | L19: 0 | M19: 0 | N19: 0 | O19: 0 | P19: 0 | Q19: 0 | R19: 0 | S19: 0 | T19: 0 | U19: 0 | V19: 1.25 | W19: 1.25 | X19: 3.75 | Z19: P2 | AA19: =L3*$D$3 -> 24537.25 | AB19: =M3*$D$3 -> 0 | AC19: =N3*$D$3 -> 9814.9 | AD19: =O3*$D$3 -> 49074.5 | AE19: =P3*$D$3 -> 0 | AF19: =Q3*$D$3 -> 0 | AG19: =R3*$D$3 -> 0 | AH19: =S3*$D$3 -> 19629.8 | ... AM19: =X3*$D$3 -> 0
A20: P19 | B20: 1435200 | C20: 2005.6651 | D20: 33569.95 | E20: 10.5 | F20: 344045.63 | G20: 399642.26 | K20: P19 | L20: 0 | M20: 0 | N20: 0 | O20: 0 | P20: 0 | Q20: 0 | R20: 0 | S20: 0 | T20: 0 | U20: 0 | V20: 0 | W20: 4.25 | X20: 6.25 | Z20: P3 | AA20: =L4*$D$4 -> 0 | AB20: =M4*$D$4 -> 20039.163 | AC20: =N4*$D$4 -> 8588.2125 | AD20: =O4*$D$4 -> 34352.85 | AE20: =P4*$D$4 -> 0 | AF20: =Q4*$D$4 -> 0 | AG20: =R4*$D$4 -> 0 | AH20: =S4*$D$4 -> 0 | ... AM20: =X4*$D$4 -> 0
A21: P20 | B21: 1170000 | C21: 1662.5398 | D21: 24008.7 | E21: 5.75 | F21: 153998.91 | G21: 156519.3 | K21: P20 | L21: 0 | M21: 0 | N21: 0 | O21: 0 | P21: 0 | Q21: 0 | R21: 0 | S21: 0 | T21: 0 | U21: 0 | V21: 0.75 | W21: 2 | X21: 3 | Z21: P4 | AA21: =L5*$D$5 -> 15248.3 | AB21: =M5*$D$5 -> 30496.6 | AC21: =N5*$D$5 -> 0 | AD21: =O5*$D$5 -> 45744.9 | AE21: =P5*$D$5 -> 0 | AF21: =Q5*$D$5 -> 0 | AG21: =R5*$D$5 -> 3812.075 | AH21: =S5*$D$5 -> 19060.375 | ... AM21: =X5*$D$5 -> 0
D22: =SUM(D2:D21) -> 336238.15 | Z22: P5 | AA22: =L6*$D$6 -> 0 | AB22: =M6*$D$6 -> 16589.25 | AC22: =N6*$D$6 -> 8294.625 | AD22: =O6*$D$6 -> 38708.25 | AE22: =P6*$D$6 -> 0 | AF22: =Q6*$D$6 -> 0 | AG22: =R6*$D$6 -> 0 | AH22: =S6*$D$6 -> 0 | ... AM22: =X6*$D$6 -> 0
Z23: P6 | AA23: =L7*$D$7 -> 5857.65 | AB23: =M7*$D$7 -> 9762.75 | AC23: =N7*$D$7 -> 3905.1 | AD23: =O7*$D$7 -> 23430.6 | AE23: =P7*$D$7 -> 0 | AF23: =Q7*$D$7 -> 0 | AG23: =R7*$D$7 -> 0 | AH23: =S7*$D$7 -> 7810.2 | ... AM23: =X7*$D$7 -> 0
K24: Proportion | L24: A | M24: B | N24: C | O24: D | P24: E | Q24: F | R24: G | S24: H | T24: I | U24: J | V24: K | W24: L | X24: M | Z24: P7 | AA24: =L8*$D$8 -> 0 | AB24: =M8*$D$8 -> 0 | AC24: =N8*$D$8 -> 16037.55 | AD24: =O8*$D$8 -> 74841.9 | AE24: =P8*$D$8 -> 21383.4 | AF24: =Q8*$D$8 -> 32075.1 | AG24: =R8*$D$8 -> 0 | AH24: =S8*$D$8 -> 0 | ... AM24: =X8*$D$8 -> 0
K25: P1 | L25: =L2/$E$2 -> 0.078431373 | M25: =M2/$E$2 -> 0.39215686 | N25: =N2/$E$2 -> 0.039215686 | O25: =O2/$E$2 -> 0.19607843 | P25: =P2/$E$2 -> 0 | Q25: =Q2/$E$2 -> 0 | R25: =R2/$E$2 -> 0 | S25: =S2/$E$2 -> 0 | ... X25: =X2/$E$2 -> 0 | Z25: P8 | AA25: =L9*$D$9 -> 0 | AB25: =M9*$D$9 -> 0 | AC25: =N9*$D$9 -> 0 | AD25: =O9*$D$9 -> 0 | AE25: =P9*$D$9 -> 10472 | AF25: =Q9*$D$9 -> 0 | AG25: =R9*$D$9 -> 0 | AH25: =S9*$D$9 -> 16755.2 | ... AM25: =X9*$D$9 -> 0
K26: P2 | L26: =L3/$E$3 -> 0.16129032 | M26: =M3/$E$3 -> 0 | N26: =N3/$E$3 -> 0.064516129 | O26: =O3/$E$3 -> 0.32258065 | P26: =P3/$E$3 -> 0 | Q26: =Q3/$E$3 -> 0 | R26: =R3/$E$3 -> 0 | S26: =S3/$E$3 -> 0.12903226 | ... X26: =X3/$E$3 -> 0 | Z26: P9 | AA26: =L10*$D$10 -> 0 | AB26: =M10*$D$10 -> 0 | AC26: =N10*$D$10 -> 0 | AD26: =O10*$D$10 -> 0 | AE26: =P10*$D$10 -> 16665 | AF26: =Q10*$D$10 -> 23331 | AG26: =R10*$D$10 -> 16665 | AH26: =S10*$D$10 -> 0 | ... AM26: =X10*$D$10 -> 0
K27: P3 | L27: =L4/$E$4 -> 0 | M27: =M4/$E$4 -> 0.18421053 | N27: =N4/$E$4 -> 0.078947368 | O27: =O4/$E$4 -> 0.31578947 | P27: =P4/$E$4 -> 0 | Q27: =Q4/$E$4 -> 0 | R27: =R4/$E$4 -> 0 | S27: =S4/$E$4 -> 0 | ... X27: =X4/$E$4 -> 0 | Z27: P10 | AA27: =L11*$D$11 -> 0 | AB27: =M11*$D$11 -> 0 | AC27: =N11*$D$11 -> 0 | AD27: =O11*$D$11 -> 0 | AE27: =P11*$D$11 -> 12227.1 | AF27: =Q11*$D$11 -> 14264.95 | AG27: =R11*$D$11 -> 0 | AH27: =S11*$D$11 -> 0 | ... AM27: =X11*$D$11 -> 0
K28: P4 | L28: =L5/$E$5 -> 0.13333333 | M28: =M5/$E$5 -> 0.26666667 | N28: =N5/$E$5 -> 0 | O28: =O5/$E$5 -> 0.4 | P28: =P5/$E$5 -> 0 | Q28: =Q5/$E$5 -> 0 | R28: =R5/$E$5 -> 0.033333333 | S28: =S5/$E$5 -> 0.16666667 | ... X28: =X5/$E$5 -> 0 | Z28: P11 | AA28: =L12*$D$12 -> 0 | AB28: =M12*$D$12 -> 0 | AC28: =N12*$D$12 -> 0 | AD28: =O12*$D$12 -> 0 | AE28: =P12*$D$12 -> 39051 | AF28: =Q12*$D$12 -> 0 | AG28: =R12*$D$12 -> 11715.3 | AH28: =S12*$D$12 -> 0 | ... AM28: =X12*$D$12 -> 0
K29: P5 | L29: =L6/$E$6 -> 0 | M29: =M6/$E$6 -> 0.2 | N29: =N6/$E$6 -> 0.1 | O29: =O6/$E$6 -> 0.46666667 | P29: =P6/$E$6 -> 0 | Q29: =Q6/$E$6 -> 0 | R29: =R6/$E$6 -> 0 | S29: =S6/$E$6 -> 0 | ... X29: =X6/$E$6 -> 0 | Z29: P12 | AA29: =L13*$D$13 -> 0 | AB29: =M13*$D$13 -> 0 | AC29: =N13*$D$13 -> 0 | AD29: =O13*$D$13 -> 0 | AE29: =P13*$D$13 -> 18947.4 | AF29: =Q13*$D$13 -> 18947.4 | AG29: =R13*$D$13 -> 9473.7 | AH29: =S13*$D$13 -> 0 | ... AM29: =X13*$D$13 -> 0
K30: P6 | L30: =L7/$E$7 -> 0.071428571 | M30: =M7/$E$7 -> 0.11904762 | N30: =N7/$E$7 -> 0.047619048 | O30: =O7/$E$7 -> 0.28571429 | P30: =P7/$E$7 -> 0 | Q30: =Q7/$E$7 -> 0 | R30: =R7/$E$7 -> 0 | S30: =S7/$E$7 -> 0.095238095 | ... X30: =X7/$E$7 -> 0 | Z30: P13 | AA30: =L14*$D$14 -> 0 | AB30: =M14*$D$14 -> 0 | AC30: =N14*$D$14 -> 0 | AD30: =O14*$D$14 -> 0 | AE30: =P14*$D$14 -> 11842.125 | AF30: =Q14*$D$14 -> 21315.825 | AG30: =R14*$D$14 -> 7105.275 | AH30: =S14*$D$14 -> 18947.4 | ... AM30: =X14*$D$14 -> 0
K31: P7 | L31: =L8/$E$8 -> 0 | M31: =M8/$E$8 -> 0 | N31: =N8/$E$8 -> 0.075 | O31: =O8/$E$8 -> 0.35 | P31: =P8/$E$8 -> 0.1 | Q31: =Q8/$E$8 -> 0.15 | R31: =R8/$E$8 -> 0 | S31: =S8/$E$8 -> 0 | ... X31: =X8/$E$8 -> 0 | Z31: P14 | AA31: =L15*$D$15 -> 0 | AB31: =M15*$D$15 -> 0 | AC31: =N15*$D$15 -> 0 | AD31: =O15*$D$15 -> 0 | AE31: =P15*$D$15 -> 28212.5 | AF31: =Q15*$D$15 -> 42318.75 | AG31: =R15*$D$15 -> 14106.25 | AH31: =S15*$D$15 -> 49371.875 | ... AM31: =X15*$D$15 -> 0
K32: P8 | L32: =L9/$E$9 -> 0 | M32: =M9/$E$9 -> 0 | N32: =N9/$E$9 -> 0 | O32: =O9/$E$9 -> 0 | P32: =P9/$E$9 -> 0.26315789 | Q32: =Q9/$E$9 -> 0 | R32: =R9/$E$9 -> 0 | S32: =S9/$E$9 -> 0.42105263 | ... X32: =X9/$E$9 -> 0 | Z32: P15 | AA32: =L16*$D$16 -> 0 | AB32: =M16*$D$16 -> 0 | AC32: =N16*$D$16 -> 0 | AD32: =O16*$D$16 -> 0 | AE32: =P16*$D$16 -> 3141.6 | AF32: =Q16*$D$16 -> 5236 | AG32: =R16*$D$16 -> 2094.4 | AH32: =S16*$D$16 -> 10472 | ... AM32: =X16*$D$16 -> 0
K33: P9 | L33: =L10/$E$10 -> 0 | M33: =M10/$E$10 -> 0 | N33: =N10/$E$10 -> 0 | O33: =O10/$E$10 -> 0 | P33: =P10/$E$10 -> 0.14705882 | Q33: =Q10/$E$10 -> 0.20588235 | R33: =R10/$E$10 -> 0.14705882 | S33: =S10/$E$10 -> 0 | ... X33: =X10/$E$10 -> 0 | Z33: P16 | AA33: =L17*$D$17 -> 0 | AB33: =M17*$D$17 -> 0 | AC33: =N17*$D$17 -> 0 | AD33: =O17*$D$17 -> 0 | AE33: =P17*$D$17 -> 0 | AF33: =Q17*$D$17 -> 24808.125 | AG33: =R17*$D$17 -> 0 | AH33: =S17*$D$17 -> 99232.5 | ... AM33: =X17*$D$17 -> 0
K34: P10 | L34: =L11/$E$11 -> 0 | M34: =M11/$E$11 -> 0 | N34: =N11/$E$11 -> 0 | O34: =O11/$E$11 -> 0 | P34: =P11/$E$11 -> 0.23076923 | Q34: =Q11/$E$11 -> 0.26923077 | R34: =R11/$E$11 -> 0 | S34: =S11/$E$11 -> 0 | ... X34: =X11/$E$11 -> 0 | Z34: P17 | AA34: =L18*$D$18 -> 0 | AB34: =M18*$D$18 -> 0 | AC34: =N18*$D$18 -> 0 | AD34: =O18*$D$18 -> 0 | AE34: =P18*$D$18 -> 0 | AF34: =Q18*$D$18 -> 0 | AG34: =R18*$D$18 -> 0 | AH34: =S18*$D$18 -> 0 | ... AM34: =X18*$D$18 -> 33157.95
K35: P11 | L35: =L12/$E$12 -> 0 | M35: =M12/$E$12 -> 0 | N35: =N12/$E$12 -> 0 | O35: =O12/$E$12 -> 0 | P35: =P12/$E$12 -> 0.625 | Q35: =Q12/$E$12 -> 0 | R35: =R12/$E$12 -> 0.1875 | S35: =S12/$E$12 -> 0 | ... X35: =X12/$E$12 -> 0 | Z35: P18 | AA35: =L19*$D$19 -> 0 | AB35: =M19*$D$19 -> 0 | AC35: =N19*$D$19 -> 0 | AD35: =O19*$D$19 -> 0 | AE35: =P19*$D$19 -> 0 | AF35: =Q19*$D$19 -> 0 | AG35: =R19*$D$19 -> 0 | AH35: =S19*$D$19 -> 0 | ... AM35: =X19*$D$19 -> 79574.625
K36: P12 | L36: =L13/$E$13 -> 0 | M36: =M13/$E$13 -> 0 | N36: =N13/$E$13 -> 0 | O36: =O13/$E$13 -> 0 | P36: =P13/$E$13 -> 0.16666667 | Q36: =Q13/$E$13 -> 0.16666667 | R36: =R13/$E$13 -> 0.083333333 | S36: =S13/$E$13 -> 0 | ... X36: =X13/$E$13 -> 0 | Z36: P19 | AA36: =L20*$D$20 -> 0 | AB36: =M20*$D$20 -> 0 | AC36: =N20*$D$20 -> 0 | AD36: =O20*$D$20 -> 0 | AE36: =P20*$D$20 -> 0 | AF36: =Q20*$D$20 -> 0 | AG36: =R20*$D$20 -> 0 | AH36: =S20*$D$20 -> 0 | ... AM36: =X20*$D$20 -> 209812.19
K37: P13 | L37: =L14/$E$14 -> 0 | M37: =M14/$E$14 -> 0 | N37: =N14/$E$14 -> 0 | O37: =O14/$E$14 -> 0 | P37: =P14/$E$14 -> 0.16666667 | Q37: =Q14/$E$14 -> 0.3 | R37: =R14/$E$14 -> 0.1 | S37: =S14/$E$14 -> 0.26666667 | ... X37: =X14/$E$14 -> 0 | Z37: P20 | AA37: =L21*$D$21 -> 0 | AB37: =M21*$D$21 -> 0 | AC37: =N21*$D$21 -> 0 | AD37: =O21*$D$21 -> 0 | AE37: =P21*$D$21 -> 0 | AF37: =Q21*$D$21 -> 0 | AG37: =R21*$D$21 -> 0 | AH37: =S21*$D$21 -> 0 | ... AM37: =X21*$D$21 -> 72026.1
K38: P14 | L38: =L15/$E$15 -> 0 | M38: =M15/$E$15 -> 0 | N38: =N15/$E$15 -> 0 | O38: =O15/$E$15 -> 0 | P38: =P15/$E$15 -> 0.21052632 | Q38: =Q15/$E$15 -> 0.31578947 | R38: =R15/$E$15 -> 0.10526316 | S38: =S15/$E$15 -> 0.36842105 | ... X38: =X15/$E$15 -> 0 | Z38: Sum | AA38: =SUM(AA18:AA37) -> 80876.65 | AB38: =SUM(AB18:AB37) -> 253055.01 | AC38: =SUM(AC18:AC37) -> 64257.113 | AD38: =SUM(AD18:AD37) -> 354236.62 | AE38: =SUM(AE18:AE37) -> 161942.12 | AF38: =SUM(AF18:AF37) -> 182297.15 | AG38: =SUM(AG18:AG37) -> 64972 | AH38: =SUM(AH18:AH37) -> 241279.35 | ... AM38: =SUM(AM18:AM37) -> 394570.86
K39: P15 | L39: =L16/$E$16 -> 0 | M39: =M16/$E$16 -> 0 | N39: =N16/$E$16 -> 0 | O39: =O16/$E$16 -> 0 | P39: =P16/$E$16 -> 0.1 | Q39: =Q16/$E$16 -> 0.16666667 | R39: =R16/$E$16 -> 0.066666667 | S39: =S16/$E$16 -> 0.33333333 | ... X39: =X16/$E$16 -> 0 | Z39: Sum Capacity | AA39: =5*16*60*L78 -> 96000 | AB39: =5*16*60*M78 -> 288000 | AC39: =5*16*60*N78 -> 76800 | AD39: =5*16*60*O78 -> 403200 | AE39: =5*16*60*P78 -> 187200 | AF39: =5*16*60*Q78 -> 211200 | AG39: =5*16*60*R78 -> 76800 | AH39: =5*16*60*S78 -> 273600 | ... AM39: =5*16*60*X78 -> 451200
K40: P16 | L40: =L17/$E$17 -> 0 | M40: =M17/$E$17 -> 0 | N40: =N17/$E$17 -> 0 | O40: =O17/$E$17 -> 0 | P40: =P17/$E$17 -> 0 | Q40: =Q17/$E$17 -> 0.125 | R40: =R17/$E$17 -> 0 | S40: =S17/$E$17 -> 0.5 | ... X40: =X17/$E$17 -> 0 | Z40: Utilization | AA40: =AA38/AA39 -> 0.8424651 | AB40: =AB38/AB39 -> 0.87866324 | AC40: =AC38/AC39 -> 0.83668115 | AD40: =AD38/AD39 -> 0.87856306 | AE40: =AE38/AE39 -> 0.86507545 | AF40: =AF38/AF39 -> 0.86314938 | AG40: =AG38/AG39 -> 0.84598958 | AH40: =AH38/AH39 -> 0.88186897 | ... AM40: =AM38/AM39 -> 0.87449216
...

Sheet Y4
A1: Part | B1: Annual_Demand_Mean_Units | C1: Weekly_Demand_StdDev_Units | D1: Weekly_Robust_Demand_99p5_Units | E1: Total_Minutes_Per_Unit | F1: Weekly_Robust_Net_Minutes | G1: Weekly_Robust_Gross_Minutes | K1: Time | L1: A | M1: B | N1: C | O1: D | P1: E | Q1: F | R1: G | S1: H | T1: I | U1: J | V1: K | W1: L | X1: M | Z1: Distance | AA1: A | AB1: B | AC1: C | AD1: D | AE1: E | AF1: F | AG1: G | AH1: H | AI1: I | AJ1: J | AK1: K | AL1: L | AM1: M
A2: P1 | B2: 1482000 | C2: 2923.1832 | D2: 36000.825 | E2: 12.75 | F2: 459377.67 | G2: 520420.09 | K2: P1 | L2: 1 | M2: 5 | N2: 0.5 | O2: 2.5 | P2: 0 | Q2: 0 | R2: 0 | S2: 0 | T2: 1.25 | U2: 2.5 | V2: 0 | W2: 0 | X2: 0 | Z2: A | AA2: 0 | AB2: 146 | AC2: 311 | AD2: 0 | AE2: 0 | AF2: 0 | AG2: 0 | AH2: 0 | AI2: 0 | AJ2: 0 | AK2: 0 | AL2: 0 | AM2: 0
A3: P2 | B3: 790400 | C3: 1501.8738 | D3: 19095.9 | E3: 7.75 | F3: 147781.42 | G3: 167792.77 | K3: P2 | L3: 1.25 | M3: 0 | N3: 0.5 | O3: 2.5 | P3: 0 | Q3: 0 | R3: 0 | S3: 1 | T3: 0 | U3: 2.5 | V3: 0 | W3: 0 | X3: 0 | Z3: B | AA3: 146 | AB3: 0 | AC3: 165 | AD3: 357 | AE3: 0 | AF3: 0 | AG3: 0 | AH3: 0 | AI3: 0 | AJ3: 0 | AK3: 0 | AL3: 0 | AM3: 0
A4: P3 | B4: 1112800 | C4: 1979.4254 | D4: 12937.2 | E4: 9.5 | F4: 251737.29 | G4: 139346.26 | K4: P3 | L4: 0 | M4: 1.75 | N4: 0.75 | O4: 3 | P4: 0 | Q4: 0 | R4: 0 | S4: 0 | T4: 1.5 | U4: 2.5 | V4: 0 | W4: 0 | X4: 0 | Z4: C | AA4: 0 | AB4: 0 | AC4: 0 | AD4: 193 | AE4: 0 | AF4: 0 | AG4: 0 | AH4: 0 | AI4: =236+211 -> 447 | AJ4: 0 | AK4: 0 | AL4: 0 | AM4: 0
A5: P4 | B5: 561600 | C5: 1450 | D5: 15620.4 | E5: 7.5 | F5: 109012.14 | G5: 132826.53 | K5: P4 | L5: 1 | M5: 2 | N5: 0 | O5: 3 | P5: 0 | Q5: 0 | R5: 0.25 | S5: 1.25 | T5: 0 | U5: 0 | V5: 0 | W5: 0 | X5: 0 | Z5: D | AA5: 0 | AB5: 0 | AC5: 193 | AD5: 0 | AE5: 0 | AF5: 0 | AG5: 89 | AH5: =209+219 -> 428 | AI5: =428+209 -> 637 | AJ5: 0 | AK5: 0 | AL5: 0 | AM5: 0
A6: P5 | B6: 556400 | C6: 1289.3797 | D6: 10908 | E6: 7.5 | F6: 105159.17 | G6: 92755.102 | K6: P5 | L6: 0 | M6: 1.5 | N6: 0.75 | O6: 3.5 | P6: 0 | Q6: 0 | R6: 0 | S6: 0 | T6: 1.75 | U6: 0 | V6: 0 | W6: 0 | X6: 0 | Z6: E | AA6: 0 | AB6: 0 | AC6: 0 | AD6: 0 | AE6: 0 | AF6: 282 | AG6: 485 | AH6: =633+131 -> 764 | AI6: 0 | AJ6: 0 | AK6: 0 | AL6: 0 | AM6: 0
A7: P6 | B7: 577200 | C7: 632.94945 | D7: 8272.425 | E7: 10.5 | F7: 133668.88 | G7: 98481.25 | K7: P6 | L7: 0.75 | M7: 1.25 | N7: 0.5 | O7: 3 | P7: 0 | Q7: 0 | R7: 0 | S7: 1 | T7: 1.25 | U7: 2.75 | V7: 0 | W7: 0 | X7: 0 | Z7: F | AA7: 0 | AB7: 0 | AC7: 89 | AD7: 0 | AE7: 0 | AF7: 0 | AG7: 202 | AH7: 350 | AI7: =287+123 -> 410 | AJ7: 0 | AK7: 0 | AL7: 0 | AM7: 0
A8: P7 | B8: 878800 | C8: 1189.8004 | D8: 20109.6 | E8: 10 | F8: 199647.23 | G8: 228000 | K8: P7 | L8: 0 | M8: 0 | N8: 0.75 | O8: 3.5 | P8: 1 | Q8: 1.5 | R8: 0 | S8: 0 | T8: 1.25 | U8: 2 | V8: 0 | W8: 0 | X8: 0 | Z8: G | AA8: 0 | AB8: 0 | AC8: 0 | AD8: 0 | AE8: =489 -> 489 | AF8: 202 | AG8: 0 | AH8: =148+131 -> 279 | AI8: =489+121 -> 610 | AJ8: 0 | AK8: 0 | AL8: 0 | AM8: 0
A9: P8 | B9: 1019200 | C9: 1870.9957 | D9: 9424.8 | E9: 4.75 | F9: 115991.99 | G9: 50757.143 | K9: P8 | L9: 0 | M9: 0 | N9: 0 | O9: 0 | P9: 1.25 | Q9: 0 | R9: 0 | S9: 2 | T9: 1 | U9: 0.5 | V9: 0 | W9: 0 | X9: 0 | Z9: H | AA9: 0 | AB9: 0 | AC9: 0 | AD9: 0 | AE9: 0 | AF9: 0 | AG9: 0 | AH9: 0 | AI9: =636 -> 636 | AJ9: =317 -> 317 | AK9: 0 | AL9: 0 | AM9: 0
A10: P9 | B10: 686400 | C10: 1360.1471 | D10: 12423 | E10: 8.5 | F10: 141979.81 | G10: 119722.79 | K10: P9 | L10: 0 | M10: 0 | N10: 0 | O10: 0 | P10: 1.25 | Q10: 1.75 | R10: 1.25 | S10: 0 | T10: 1.25 | U10: 3 | V10: 0 | W10: 0 | X10: 0 | Z10: I | AA10: 0 | AB10: 0 | AC10: 0 | AD10: 0 | AE10: 0 | AF10: 0 | AG10: 0 | AH10: 0 | AI10: 0 | AJ10: =319 -> 319 | AK10: 0 | AL10: 0 | AM10: 0
A11: P10 | B11: 395200 | C11: 738.66434 | D11: 8300.325 | E11: 6.5 | F11: 61767.376 | G11: 61170.196 | K11: P10 | L11: 0 | M11: 0 | N11: 0 | O11: 0 | P11: 1.5 | Q11: 1.75 | R11: 0 | S11: 0 | T11: 1.25 | U11: 2 | V11: 0 | W11: 0 | X11: 0 | Z11: J | AA11: 0 | AB11: 0 | AC11: 0 | AD11: 0 | AE11: 0 | AF11: 0 | AG11: 0 | AH11: 0 | AI11: 319 | AJ11: 0 | AK11: 0 | AL11: 0 | AM11: 0
A12: P11 | B12: 1164800 | C12: 1939.0719 | D12: 16544.85 | E12: 4 | F12: 109578.87 | G12: 75033.333 | K12: P11 | L12: 0 | M12: 0 | N12: 0 | O12: 0 | P12: 2.5 | Q12: 0 | R12: 0.75 | S12: 0 | T12: 0.75 | U12: 0 | V12: 0 | W12: 0 | X12: 0 | Z12: K | AA12: 0 | AB12: 0 | AC12: 0 | AD12: 0 | AE12: 0 | AF12: 0 | AG12: 0 | AH12: 0 | AI12: 0 | AJ12: 0 | AK12: 0 | AL12: 85.5 | AM12: 95
A13: P12 | B13: 1310400 | C13: 1800 | D13: 19040.1 | E13: 6 | F13: 179018.96 | G13: 129524.49 | K13: P12 | L13: 0 | M13: 0 | N13: 0 | O13: 0 | P13: 1 | Q13: 1 | R13: 0.5 | S13: 0 | T13: 1.25 | U13: 2.25 | V13: 0 | W13: 0 | X13: 0 | Z13: L | AA13: 0 | AB13: 0 | AC13: 0 | AD13: 0 | AE13: 0 | AF13: 0 | AG13: 0 | AH13: 0 | AI13: 0 | AJ13: 0 | AK13: 85.5 | AL13: 0 | AM13: =85.5+95 -> 180.5
A14: P13 | B14: 629200 | C14: 984.88578 | D14: 9520.05 | E14: 7.5 | F14: 109776.73 | G14: 80952.806 | K14: P13 | L14: 0 | M14: 0 | N14: 0 | O14: 0 | P14: 1.25 | Q14: 2.25 | R14: 0.75 | S14: 2 | T14: 1.25 | U14: 0 | V14: 0 | W14: 0 | X14: 0 | Z14: M | AA14: 0 | AB14: 0 | AC14: 0 | AD14: 0 | AE14: 0 | AF14: 0 | AG14: 0 | AH14: 0 | AI14: 0 | AJ14: 0 | AK14: 0 | AL14: =180.5 -> 180.5 | AM14: 0
A15: P14 | B15: 1341600 | C15: 1714.6428 | D15: 27190.2 | E15: 4.75 | F15: 143528.98 | G15: 146432.48 | K15: P14 | L15: 0 | M15: 0 | N15: 0 | O15: 0 | P15: 1 | Q15: 1.5 | R15: 0.5 | S15: 1.75 | T15: 0 | U15: 0 | V15: 0 | W15: 0 | X15: 0
A16: P15 | B16: 488800 | C16: 1138.2552 | D16: 4712.4 | E16: 7.5 | F16: 92489.634 | G16: 40071.429 | K16: P15 | L16: 0 | M16: 0 | N16: 0 | O16: 0 | P16: 0.75 | Q16: 1.25 | R16: 0.5 | S16: 2.5 | T16: 0 | U16: 2.5 | V16: 0 | W16: 0 | X16: 0
A17: P16 | B17: 696800 | C17: 2404.6829 | D17: 20301 | E17: 10 | F17: 195940.53 | G17: 230170.07 | K17: P16 | L17: 0 | M17: 0 | N17: 0 | O17: 0 | P17: 0 | Q17: 1.25 | R17: 0 | S17: 5 | T17: 1.25 | U17: 2.5 | V17: 0 | W17: 0 | X17: 0 | Z17: Capacity | AA17: A | AB17: B | AC17: C | AD17: D | AE17: E | AF17: F | AG17: G | AH17: H | AI17: I | AJ17: J | AK17: K | AL17: L | AM17: M
A18: P17 | B18: 800800 | C18: 1051.487 | D18: 9520.05 | E18: 7.25 | F18: 131286.27 | G18: 78254.379 | K18: P17 | L18: 0 | M18: 0 | N18: 0 | O18: 0 | P18: 0 | Q18: 0 | R18: 0 | S18: 0 | T18: 0 | U18: 0 | V18: 0.75 | W18: 3 | X18: 3.5 | Z18: P1 | AA18: =L2*$D$2 -> 36000.825 | AB18: =M2*$D$2 -> 180004.12 | AC18: =N2*$D$2 -> 18000.412 | AD18: =O2*$D$2 -> 90002.062 | AE18: =P2*$D$2 -> 0 | AF18: =Q2*$D$2 -> 0 | AG18: =R2*$D$2 -> 0 | AH18: =S2*$D$2 -> 0 | ... AM18: =X2*$D$2 -> 0
A19: P18 | B19: 1076400 | C19: 1304.7988 | D19: 20555.1 | E19: 6.25 | F19: 150380.87 | G19: 145656.89 | K19: P18 | L19: 0 | M19: 0 | N19: 0 | O19: 0 | P19: 0 | Q19: 0 | R19: 0 | S19: 0 | T19: 0 | U19: 0 | V19: 1.25 | W19: 1.25 | X19: 3.75 | Z19: P2 | AA19: =L3*$D$3 -> 23869.875 | AB19: =M3*$D$3 -> 0 | AC19: =N3*$D$3 -> 9547.95 | AD19: =O3*$D$3 -> 47739.75 | AE19: =P3*$D$3 -> 0 | AF19: =Q3*$D$3 -> 0 | AG19: =R3*$D$3 -> 0 | AH19: =S3*$D$3 -> 19095.9 | ... AM19: =X3*$D$3 -> 0
A20: P19 | B20: 1528800 | C20: 2934.8126 | D20: 34753.2 | E20: 10.5 | F20: 388075.55 | G20: 413728.57 | K20: P19 | L20: 0 | M20: 0 | N20: 0 | O20: 0 | P20: 0 | Q20: 0 | R20: 0 | S20: 0 | T20: 0 | U20: 0 | V20: 0 | W20: 4.25 | X20: 6.25 | Z20: P3 | AA20: =L4*$D$4 -> 0 | AB20: =M4*$D$4 -> 22640.1 | AC20: =N4*$D$4 -> 9702.9 | AD20: =O4*$D$4 -> 38811.6 | AE20: =P4*$D$4 -> 0 | AF20: =Q4*$D$4 -> 0 | AG20: =R4*$D$4 -> 0 | AH20: =S4*$D$4 -> 0 | ... AM20: =X4*$D$4 -> 0
A21: P20 | B21: 1242800 | C21: 2240.5357 | D21: 24188.1 | E21: 5.75 | F21: 170609.61 | G21: 157688.86 | K21: P20 | L21: 0 | M21: 0 | N21: 0 | O21: 0 | P21: 0 | Q21: 0 | R21: 0 | S21: 0 | T21: 0 | U21: 0 | V21: 0.75 | W21: 2 | X21: 3 | Z21: P4 | AA21: =L5*$D$5 -> 15620.4 | AB21: =M5*$D$5 -> 31240.8 | AC21: =N5*$D$5 -> 0 | AD21: =O5*$D$5 -> 46861.2 | AE21: =P5*$D$5 -> 0 | AF21: =Q5*$D$5 -> 0 | AG21: =R5*$D$5 -> 3905.1 | AH21: =S5*$D$5 -> 19525.5 | ... AM21: =X5*$D$5 -> 0
D22: =SUM(D2:D21) -> 339417.52 | Z22: P5 | AA22: =L6*$D$6 -> 0 | AB22: =M6*$D$6 -> 16362 | AC22: =N6*$D$6 -> 8181 | AD22: =O6*$D$6 -> 38178 | AE22: =P6*$D$6 -> 0 | AF22: =Q6*$D$6 -> 0 | AG22: =R6*$D$6 -> 0 | AH22: =S6*$D$6 -> 0 | ... AM22: =X6*$D$6 -> 0
Z23: P6 | AA23: =L7*$D$7 -> 6204.3187 | AB23: =M7*$D$7 -> 10340.531 | AC23: =N7*$D$7 -> 4136.2125 | AD23: =O7*$D$7 -> 24817.275 | AE23: =P7*$D$7 -> 0 | AF23: =Q7*$D$7 -> 0 | AG23: =R7*$D$7 -> 0 | AH23: =S7*$D$7 -> 8272.425 | ... AM23: =X7*$D$7 -> 0
K24: Proportion | L24: A | M24: B | N24: C | O24: D | P24: E | Q24: F | R24: G | S24: H | T24: I | U24: J | V24: K | W24: L | X24: M | Z24: P7 | AA24: =L8*$D$8 -> 0 | AB24: =M8*$D$8 -> 0 | AC24: =N8*$D$8 -> 15082.2 | AD24: =O8*$D$8 -> 70383.6 | AE24: =P8*$D$8 -> 20109.6 | AF24: =Q8*$D$8 -> 30164.4 | AG24: =R8*$D$8 -> 0 | AH24: =S8*$D$8 -> 0 | ... AM24: =X8*$D$8 -> 0
K25: P1 | L25: =L2/$E$2 -> 0.078431373 | M25: =M2/$E$2 -> 0.39215686 | N25: =N2/$E$2 -> 0.039215686 | O25: =O2/$E$2 -> 0.19607843 | P25: =P2/$E$2 -> 0 | Q25: =Q2/$E$2 -> 0 | R25: =R2/$E$2 -> 0 | S25: =S2/$E$2 -> 0 | ... X25: =X2/$E$2 -> 0 | Z25: P8 | AA25: =L9*$D$9 -> 0 | AB25: =M9*$D$9 -> 0 | AC25: =N9*$D$9 -> 0 | AD25: =O9*$D$9 -> 0 | AE25: =P9*$D$9 -> 11781 | AF25: =Q9*$D$9 -> 0 | AG25: =R9*$D$9 -> 0 | AH25: =S9*$D$9 -> 18849.6 | ... AM25: =X9*$D$9 -> 0
